Workbook
Name TotalMonthlyExpenses: SUM(#REF!)
Name TotalMonthlyIncome: SUM(#REF!)

Sheet 대시보드
C2: (주) 넷폼알앤디 2026년 매출현황 | S2: 기준일자 | T2: =TODAY()-1 -> 46173
C6: 목표매출 | E6: 계약매출 | G6: 확정매출 | I6: 달성률 | K6: 수금예정액(v-) | M6: 관리미수금(v-) | O6: 수금률
C7: 23000000000 | E7: =Q13 -> 1.1832764e+10 | G7: =Q17 -> 7.5955742e+09 | I7: =IF(C7>0, G7/C7, 0) -> 0.33024235 | K7: =G32 -> 3574579090 | M7: =H32 -> 1152221050 | O7: =I32 -> 0.51040344
C11: 1. 월별 계약 매출
C12: 계약일기준 | D12: 25년12월 | E12: 1월 | F12: 2월 | G12: 3월 | H12: 4월 | I12: 5월 | J12: 6월 | K12: 7월 | L12: 8월 | M12: 9월 | N12: 10월 | O12: 11월 | P12: 12월 | Q12: 합계
C13: 총액 | D13: =SUMIFS(컨설팅!H:H,컨설팅!J:J,">="&DATE(2025,12,1),컨설팅!J:J,"<="&EOMONTH(DATE(2025,12,1),0))+SUMIFS(기술자문료!G:G,기술자문료!I:I,">="&DATE(2025,12,1),기술자문료!I:I,"<="&EOMONTH(DATE(2025,12,1),0))+SUMIFS(특허료!I:I,특허료!J:J,">="&DATE(2025,12,1),특허료!J:J,"<="&EOMONTH(DATE(2025,12,1),0))+SUMIFS(자재판매!P:P,자재판매!A:A,"2025-12*") -> 1441571640 | E13: =SUMIFS(컨설팅!H:H,컨설팅!J:J,">="&DATE(2026,1,1),컨설팅!J:J,"<="&EOMONTH(DATE(2026,1,1),0))+SUMIFS(기술자문료!G:G,기술자문료!I:I,">="&DATE(2026,1,1),기술자문료!I:I,"<="&EOMONTH(DATE(2026,1,1),0))+SUMIFS(특허료!I:I,특허료!J:J,">="&DATE(2026,1,1),특허료!J:J,"<="&EOMONTH(DATE(2026,1,1),0))+SUMIFS(자재판매!P:P,자재판매!A:A,"2026-01*")+D40+D41+D42 -> 299683191 | F13: =SUMIFS(컨설팅!H:H,컨설팅!J:J,">="&DATE(2026,2,1),컨설팅!J:J,"<="&EOMONTH(DATE(2026,2,1),0))+SUMIFS(기술자문료!G:G,기술자문료!I:I,">="&DATE(2026,2,1),기술자문료!I:I,"<="&EOMONTH(DATE(2026,2,1),0))+SUMIFS(특허료!I:I,특허료!J:J,">="&DATE(2026,2,1),특허료!J:J,"<="&EOMONTH(DATE(2026,2,1),0))+SUMIFS(자재판매!P:P,자재판매!A:A,"2026-02*")+E40+E41+E42 -> 415277984 | G13: =SUMIFS(컨설팅!H:H,컨설팅!J:J,">="&DATE(2026,3,1),컨설팅!J:J,"<="&EOMONTH(DATE(2026,3,1),0))+SUMIFS(기술자문료!G:G,기술자문료!I:I,">="&DATE(2026,3,1),기술자문료!I:I,"<="&EOMONTH(DATE(2026,3,1),0))+SUMIFS(특허료!I:I,특허료!J:J,">="&DATE(2026,3,1),특허료!J:J,"<="&EOMONTH(DATE(2026,3,1),0))+SUMIFS(자재판매!P:P,자재판매!A:A,"2026-03*")+F40+F41+F42 -> 2515390438 | H13: =SUMIFS(컨설팅!H:H,컨설팅!J:J,">="&DATE(2026,4,1),컨설팅!J:J,"<="&EOMONTH(DATE(2026,4,1),0))+SUMIFS(기술자문료!G:G,기술자문료!I:I,">="&DATE(2026,4,1),기술자문료!I:I,"<="&EOMONTH(DATE(2026,4,1),0))+SUMIFS(특허료!I:I,특허료!J:J,">="&DATE(2026,4,1),특허료!J:J,"<="&EOMONTH(DATE(2026,4,1),0))+SUMIFS(자재판매!P:P,자재판매!A:A,"2026-04*")+G40+G41+G42 -> 4405065720 | I13: =SUMIFS(컨설팅!H:H,컨설팅!J:J,">="&DATE(2026,5,1),컨설팅!J:J,"<="&EOMONTH(DATE(2026,5,1),0))+SUMIFS(기술자문료!G:G,기술자문료!I:I,">="&DATE(2026,5,1),기술자문료!I:I,"<="&EOMONTH(DATE(2026,5,1),0))+SUMIFS(특허료!I:I,특허료!J:J,">="&DATE(2026,5,1),특허료!J:J,"<="&EOMONTH(DATE(2026,5,1),0))+SUMIFS(자재판매!P:P,자재판매!A:A,"2026-05*")+H40+H41+H42 -> 2.6811314e+09 | J13: =SUMIFS(컨설팅!H:H,컨설팅!J:J,">="&DATE(2026,6,1),컨설팅!J:J,"<="&EOMONTH(DATE(2026,6,1),0))+SUMIFS(기술자문료!G:G,기술자문료!I:I,">="&DATE(2026,6,1),기술자문료!I:I,"<="&EOMONTH(DATE(2026,6,1),0))+SUMIFS(특허료!I:I,특허료!J:J,">="&DATE(2026,6,1),특허료!J:J,"<="&EOMONTH(DATE(2026,6,1),0))+SUMIFS(자재판매!P:P,자재판매!A:A,"2026-06*")+I40+I41+I42 -> 74643800 | K13: =SUMIFS(컨설팅!H:H,컨설팅!J:J,">="&DATE(2026,7,1),컨설팅!J:J,"<="&EOMONTH(DATE(2026,7,1),0))+SUMIFS(기술자문료!G:G,기술자문료!I:I,">="&DATE(2026,7,1),기술자문료!I:I,"<="&EOMONTH(DATE(2026,7,1),0))+SUMIFS(특허료!I:I,특허료!J:J,">="&DATE(2026,7,1),특허료!J:J,"<="&EOMONTH(DATE(2026,7,1),0))+SUMIFS(자재판매!P:P,자재판매!A:A,"2026-07*")+J40+J41+J42 -> 0 | L13: =SUMIFS(컨설팅!H:H,컨설팅!J:J,">="&DATE(2026,8,1),컨설팅!J:J,"<="&EOMONTH(DATE(2026,8,1),0))+SUMIFS(기술자문료!G:G,기술자문료!I:I,">="&DATE(2026,8,1),기술자문료!I:I,"<="&EOMONTH(DATE(2026,8,1),0))+SUMIFS(특허료!I:I,특허료!J:J,">="&DATE(2026,8,1),특허료!J:J,"<="&EOMONTH(DATE(2026,8,1),0))+SUMIFS(자재판매!P:P,자재판매!A:A,"2026-08*")+K40+K41+K42 -> 0 | M13: =SUMIFS(컨설팅!H:H,컨설팅!J:J,">="&DATE(2026,9,1),컨설팅!J:J,"<="&EOMONTH(DATE(2026,9,1),0))+SUMIFS(기술자문료!G:G,기술자문료!I:I,">="&DATE(2026,9,1),기술자문료!I:I,"<="&EOMONTH(DATE(2026,9,1),0))+SUMIFS(특허료!I:I,특허료!J:J,">="&DATE(2026,9,1),특허료!J:J,"<="&EOMONTH(DATE(2026,9,1),0))+SUMIFS(자재판매!P:P,자재판매!A:A,"2026-09*")+L40+L41+L42 -> 0 | N13: =SUMIFS(컨설팅!H:H,컨설팅!J:J,">="&DATE(2026,10,1),컨설팅!J:J,"<="&EOMONTH(DATE(2026,10,1),0))+SUMIFS(기술자문료!G:G,기술자문료!I:I,">="&DATE(2026,10,1),기술자문료!I:I,"<="&EOMONTH(DATE(2026,10,1),0))+SUMIFS(특허료!I:I,특허료!J:J,">="&DATE(2026,10,1),특허료!J:J,"<="&EOMONTH(DATE(2026,10,1),0))+SUMIFS(자재판매!P:P,자재판매!A:A,"2026-10*")+M40+M41+M42 -> 0 | O13: =SUMIFS(컨설팅!H:H,컨설팅!J:J,">="&DATE(2026,11,1),컨설팅!J:J,"<="&EOMONTH(DATE(2026,11,1),0))+SUMIFS(기술자문료!G:G,기술자문료!I:I,">="&DATE(2026,11,1),기술자문료!I:I,"<="&EOMONTH(DATE(2026,11,1),0))+SUMIFS(특허료!I:I,특허료!J:J,">="&DATE(2026,11,1),특허료!J:J,"<="&EOMONTH(DATE(2026,11,1),0))+SUMIFS(자재판매!P:P,자재판매!A:A,"2026-11*")+N40+N41+N42 -> 0 | P13: =SUMIFS(컨설팅!H:H,컨설팅!J:J,">="&DATE(2026,12,1),컨설팅!J:J,"<="&EOMONTH(DATE(2026,12,1),0))+SUMIFS(기술자문료!G:G,기술자문료!I:I,">="&DATE(2026,12,1),기술자문료!I:I,"<="&EOMONTH(DATE(2026,12,1),0))+SUMIFS(특허료!I:I,특허료!J:J,">="&DATE(2026,12,1),특허료!J:J,"<="&EOMONTH(DATE(2026,12,1),0))+SUMIFS(자재판매!P:P,자재판매!A:A,"2026-12*")+O40+O41+O42 -> 0 | Q13: =SUM(D13:P13) -> 1.1832764e+10
C15: 2. 월별 확정 매출
C16: 매출일기준 | D16: 25년12월 | E16: 1월 | F16: 2월 | G16: 3월 | H16: 4월 | I16: 5월 | J16: 6월 | K16: 7월 | L16: 8월 | M16: 9월 | N16: 10월 | O16: 11월 | P16: 12월 | Q16: 합계
C17: 총액 | D17: =SUMIFS(컨설팅!H:H,컨설팅!L:L,">="&DATE(2025,12,1),컨설팅!L:L,"<="&EOMONTH(DATE(2025,12,1),0))+SUMIFS(기술자문료!G:G,기술자문료!K:K,">="&DATE(2025,12,1),기술자문료!K:K,"<="&EOMONTH(DATE(2025,12,1),0))+SUMIFS(특허료!I:I,특허료!K:K,">="&DATE(2025,12,1),특허료!K:K,"<="&EOMONTH(DATE(2025,12,1),0))+SUMIFS(자재판매!P:P,자재판매!A:A,"2025-12*") -> 53520000 | E17: =SUMIFS(컨설팅!H:H,컨설팅!L:L,">="&DATE(2026,1,1),컨설팅!L:L,"<="&EOMONTH(DATE(2026,1,1),0))+SUMIFS(기술자문료!G:G,기술자문료!K:K,">="&DATE(2026,1,1),기술자문료!K:K,"<="&EOMONTH(DATE(2026,1,1),0))+SUMIFS(특허료!I:I,특허료!K:K,">="&DATE(2026,1,1),특허료!K:K,"<="&EOMONTH(DATE(2026,1,1),0))+SUMIFS(자재판매!P:P,자재판매!A:A,"2026-01*")+D40+D41+D42 -> 309083291 | F17: =SUMIFS(컨설팅!H:H,컨설팅!L:L,">="&DATE(2026,2,1),컨설팅!L:L,"<="&EOMONTH(DATE(2026,2,1),0))+SUMIFS(기술자문료!G:G,기술자문료!K:K,">="&DATE(2026,2,1),기술자문료!K:K,"<="&EOMONTH(DATE(2026,2,1),0))+SUMIFS(특허료!I:I,특허료!K:K,">="&DATE(2026,2,1),특허료!K:K,"<="&EOMONTH(DATE(2026,2,1),0))+SUMIFS(자재판매!P:P,자재판매!A:A,"2026-02*")+E40+E41+E42 -> 249691684 | G17: =SUMIFS(컨설팅!H:H,컨설팅!L:L,">="&DATE(2026,3,1),컨설팅!L:L,"<="&EOMONTH(DATE(2026,3,1),0))+SUMIFS(기술자문료!G:G,기술자문료!K:K,">="&DATE(2026,3,1),기술자문료!K:K,"<="&EOMONTH(DATE(2026,3,1),0))+SUMIFS(특허료!I:I,특허료!K:K,">="&DATE(2026,3,1),특허료!K:K,"<="&EOMONTH(DATE(2026,3,1),0))+SUMIFS(자재판매!P:P,자재판매!A:A,"2026-03*")+F40+F41+F42 -> 1672984738 | H17: =SUMIFS(컨설팅!H:H,컨설팅!L:L,">="&DATE(2026,4,1),컨설팅!L:L,"<="&EOMONTH(DATE(2026,4,1),0))+SUMIFS(기술자문료!G:G,기술자문료!K:K,">="&DATE(2026,4,1),기술자문료!K:K,"<="&EOMONTH(DATE(2026,4,1),0))+SUMIFS(특허료!I:I,특허료!K:K,">="&DATE(2026,4,1),특허료!K:K,"<="&EOMONTH(DATE(2026,4,1),0))+SUMIFS(자재판매!P:P,자재판매!A:A,"2026-04*")+G40+G41+G42 -> 2603006539 | I17: =SUMIFS(컨설팅!H:H,컨설팅!L:L,">="&DATE(2026,5,1),컨설팅!L:L,"<="&EOMONTH(DATE(2026,5,1),0))+SUMIFS(기술자문료!G:G,기술자문료!K:K,">="&DATE(2026,5,1),기술자문료!K:K,"<="&EOMONTH(DATE(2026,5,1),0))+SUMIFS(특허료!I:I,특허료!K:K,">="&DATE(2026,5,1),특허료!K:K,"<="&EOMONTH(DATE(2026,5,1),0))+SUMIFS(자재판매!P:P,자재판매!A:A,"2026-05*")+H40+H41+H42 -> 2.5493092e+09 | J17: =SUMIFS(컨설팅!H:H,컨설팅!L:L,">="&DATE(2026,6,1),컨설팅!L:L,"<="&EOMONTH(DATE(2026,6,1),0))+SUMIFS(기술자문료!G:G,기술자문료!K:K,">="&DATE(2026,6,1),기술자문료!K:K,"<="&EOMONTH(DATE(2026,6,1),0))+SUMIFS(특허료!I:I,특허료!K:K,">="&DATE(2026,6,1),특허료!K:K,"<="&EOMONTH(DATE(2026,6,1),0))+SUMIFS(자재판매!P:P,자재판매!A:A,"2026-06*")+I40+I41+I42 -> 211498750 | K17: =SUMIFS(컨설팅!H:H,컨설팅!L:L,">="&DATE(2026,7,1),컨설팅!L:L,"<="&EOMONTH(DATE(2026,7,1),0))+SUMIFS(기술자문료!G:G,기술자문료!K:K,">="&DATE(2026,7,1),기술자문료!K:K,"<="&EOMONTH(DATE(2026,7,1),0))+SUMIFS(특허료!I:I,특허료!K:K,">="&DATE(2026,7,1),특허료!K:K,"<="&EOMONTH(DATE(2026,7,1),0))+SUMIFS(자재판매!P:P,자재판매!A:A,"2026-07*")+J40+J41+J42 -> 0 | L17: =SUMIFS(컨설팅!H:H,컨설팅!L:L,">="&DATE(2026,8,1),컨설팅!L:L,"<="&EOMONTH(DATE(2026,8,1),0))+SUMIFS(기술자문료!G:G,기술자문료!K:K,">="&DATE(2026,8,1),기술자문료!K:K,"<="&EOMONTH(DATE(2026,8,1),0))+SUMIFS(특허료!I:I,특허료!K:K,">="&DATE(2026,8,1),특허료!K:K,"<="&EOMONTH(DATE(2026,8,1),0))+SUMIFS(자재판매!P:P,자재판매!A:A,"2026-08*")+K40+K41+K42 -> 0 | M17: =SUMIFS(컨설팅!H:H,컨설팅!L:L,">="&DATE(2026,9,1),컨설팅!L:L,"<="&EOMONTH(DATE(2026,9,1),0))+SUMIFS(기술자문료!G:G,기술자문료!K:K,">="&DATE(2026,9,1),기술자문료!K:K,"<="&EOMONTH(DATE(2026,9,1),0))+SUMIFS(특허료!I:I,특허료!K:K,">="&DATE(2026,9,1),특허료!K:K,"<="&EOMONTH(DATE(2026,9,1),0))+SUMIFS(자재판매!P:P,자재판매!A:A,"2026-09*")+L40+L41+L42 -> 0 | N17: =SUMIFS(컨설팅!H:H,컨설팅!L:L,">="&DATE(2026,10,1),컨설팅!L:L,"<="&EOMONTH(DATE(2026,10,1),0))+SUMIFS(기술자문료!G:G,기술자문료!K:K,">="&DATE(2026,10,1),기술자문료!K:K,"<="&EOMONTH(DATE(2026,10,1),0))+SUMIFS(특허료!I:I,특허료!K:K,">="&DATE(2026,10,1),특허료!K:K,"<="&EOMONTH(DATE(2026,10,1),0))+SUMIFS(자재판매!P:P,자재판매!A:A,"2026-10*")+M40+M41+M42 -> 0 | O17: =SUMIFS(컨설팅!H:H,컨설팅!L:L,">="&DATE(2026,11,1),컨설팅!L:L,"<="&EOMONTH(DATE(2026,11,1),0))+SUMIFS(기술자문료!G:G,기술자문료!K:K,">="&DATE(2026,11,1),기술자문료!K:K,"<="&EOMONTH(DATE(2026,11,1),0))+SUMIFS(특허료!I:I,특허료!K:K,">="&DATE(2026,11,1),특허료!K:K,"<="&EOMONTH(DATE(2026,11,1),0))+SUMIFS(자재판매!P:P,자재판매!A:A,"2026-11*")+N40+N41+N42 -> 0 | P17: =SUMIFS(컨설팅!H:H,컨설팅!L:L,">="&DATE(2026,12,1),컨설팅!L:L,"<="&EOMONTH(DATE(2026,12,1),0))+SUMIFS(기술자문료!G:G,기술자문료!K:K,">="&DATE(2026,12,1),기술자문료!K:K,"<="&EOMONTH(DATE(2026,12,1),0))+SUMIFS(특허료!I:I,특허료!K:K,">="&DATE(2026,12,1),특허료!K:K,"<="&EOMONTH(DATE(2026,12,1),0))+SUMIFS(자재판매!P:P,자재판매!A:A,"2026-12*")+O40+O41+O42 -> 0 | Q17: =SUM(E17:P17) -> 7.5955742e+09
C23: 3. 카테고리별 매출
C24: 매출구분 | D24: 현장수 | E24: 계약매출 | F24: 확정매출 | G24: 수금예정액 | H24: 관리미수금 | I24: 수금률
C25: 컨설팅 | D25: =MAX(컨설팅!B:B) -> 64 | E25: =SUMIFS(컨설팅!H:H,컨설팅!J:J,">="&DATE(2025,12,1),컨설팅!J:J,"<="&DATE(2026,12,31)) -> 4740931740 | F25: =SUMIFS(컨설팅!H:H,컨설팅!L:L,">="&DATE(2026,1,1),컨설팅!L:L,"<="&DATE(2026,12,31)) -> 2897704640 | G25: =SUMIFS(컨설팅!P:P,컨설팅!L:L,">="&DATE(2026,1,1),컨설팅!L:L,"<="&DATE(2026,12,31))/1.1 -> 1142699590 | H25: =SUM(SUMIFS(컨설팅!P:P,컨설팅!S:S,{"관리","장기미수"},컨설팅!L:L,">="&DATE(2026,1,1),컨설팅!L:L,"<="&DATE(2026,12,31)))/1.1 -> 2.902518e+08 | I25: =IF(F25>0, SUMIFS(컨설팅!O:O,컨설팅!L:L,">="&DATE(2025,12,1),컨설팅!L:L,"<="&DATE(2026,12,31))/1.1/F25, 0) -> 0.60565353
C26: 기술자문료 | D26: =MAX(기술자문료!B:B) -> 32 | E26: =SUMIFS(기술자문료!G:G,기술자문료!I:I,">="&DATE(2025,12,1),기술자문료!I:I,"<="&DATE(2026,12,31)) -> 2620658431 | F26: =SUMIFS(기술자문료!G:G,기술자문료!K:K,">="&DATE(2026,1,1),기술자문료!K:K,"<="&DATE(2026,12,31)) -> 226695500 | G26: =SUMIFS(기술자문료!O:O,기술자문료!K:K,">="&DATE(2026,1,1),기술자문료!K:K,"<="&DATE(2026,12,31))/1.1 -> 169133500 | H26: =SUM(SUMIFS(기술자문료!O:O,기술자문료!Q:Q,{"관리","장기미수"},기술자문료!K:K,">="&DATE(2026,1,1),기술자문료!K:K,"<="&DATE(2026,12,31)))/1.1 -> 7940000 | I26: =IF(F26>0, SUMIFS(기술자문료!N:N,기술자문료!K:K,">="&DATE(2025,12,1),기술자문료!K:K,"<="&DATE(2026,12,31))/1.1/F26, 0) -> 0.49000532
C27: 특허료 | D27: =MAX(특허료!B:B) -> 21 | E27: =SUMIFS(특허료!I:I,특허료!J:J,">="&DATE(2025,12,1),특허료!J:J,"<="&DATE(2026,12,31)) -> 55052907 | F27: =SUMIFS(특허료!I:I,특허료!K:K,">="&DATE(2026,1,1),특허료!K:K,"<="&DATE(2026,12,31)) -> 55052907 | G27: =SUM(특허료!O:O)/1.1 -> 14581550 | H27: =SUM(SUMIF(특허료!P:P,{"관리","장기미수"},특허료!O:O))/1.1 -> 0 | I27: =IF(F27>0, SUM(특허료!N:N)/1.1/F27, 0) -> 0.73513569
C28: 자재판매 | D28: =ROUND(SUMPRODUCT((자재판매!AG2:AG9891<>"")/COUNTIF(자재판매!AG2:AG9891,자재판매!AG2:AG9891&"")),0) -> 321 | E28: =SUMIFS(자재판매!P:P,자재판매!A:A,"2026-*") -> 4121617598 | F28: =SUMIFS(자재판매!P:P,자재판매!A:A,"2026-*") -> 4121617598 | G28: =SUM(자재판매!AK:AK)/1.1 -> 2248164450 | H28: =SUM(SUMIF(자재판매!AL:AL,{"관리","장기미수"},자재판매!AK:AK))/1.1 -> 8.5402925e+08 | I28: =IF(F28>0, SUM(자재판매!AJ:AJ)/1.1/F28, 0) -> 0.45454317
C29: 그로홈 | D29: - | E29: =F29 -> 187893551 | F29: =P40 -> 187893551 | G29: - | H29: - | I29: -
C30: 포어스토어 | D30: - | E30: =F30 -> 106771577 | F30: =P41 -> 106771577 | G30: - | H30: - | I30: -
C31: 모여라딜 | D31: - | E31: =F31 -> -161619 | F31: =P42 -> -161619 | G31: - | H31: - | I31: -
C32: 합계 | D32: =SUM(D25:D28) -> 438 | E32: =SUM(E25:E31) -> 1.1832764e+10 | F32: =SUM(F25:F31) -> 7.5955742e+09 | G32: =SUM(G25:G31) -> 3574579090 | H32: =SUM(H25:H31) -> 1152221050 | I32: =IF(SUM(F25:F28)>0, (SUM(F25:F28)-SUM(G25:G28))/SUM(F25:F28), 0) -> 0.51040344
C34: 4. 카테고리별 월별 매출
C35: 매출구분 | D35: 1월 | E35: 2월 | F35: 3월 | G35: 4월 | H35: 5월 | I35: 6월 | J35: 7월 | K35: 8월 | L35: 9월 | M35: 10월 | N35: 11월 | O35: 12월 | P35: 합계
C36: 컨설팅 | D36: =SUMIFS(컨설팅!H:H,컨설팅!L:L,">="&DATE(2026,1,1),컨설팅!L:L,"<="&EOMONTH(DATE(2026,1,1),0)) -> 59635000 | E36: =SUMIFS(컨설팅!H:H,컨설팅!L:L,">="&DATE(2026,2,1),컨설팅!L:L,"<="&EOMONTH(DATE(2026,2,1),0)) -> 9036000 | F36: =SUMIFS(컨설팅!H:H,컨설팅!L:L,">="&DATE(2026,3,1),컨설팅!L:L,"<="&EOMONTH(DATE(2026,3,1),0)) -> 590715300 | G36: =SUMIFS(컨설팅!H:H,컨설팅!L:L,">="&DATE(2026,4,1),컨설팅!L:L,"<="&EOMONTH(DATE(2026,4,1),0)) -> 1123702650 | H36: =SUMIFS(컨설팅!H:H,컨설팅!L:L,">="&DATE(2026,5,1),컨설팅!L:L,"<="&EOMONTH(DATE(2026,5,1),0)) -> 978119940 | I36: =SUMIFS(컨설팅!H:H,컨설팅!L:L,">="&DATE(2026,6,1),컨설팅!L:L,"<="&EOMONTH(DATE(2026,6,1),0)) -> 136495750 | J36: =SUMIFS(컨설팅!H:H,컨설팅!L:L,">="&DATE(2026,7,1),컨설팅!L:L,"<="&EOMONTH(DATE(2026,7,1),0)) -> 0 | K36: =SUMIFS(컨설팅!H:H,컨설팅!L:L,">="&DATE(2026,8,1),컨설팅!L:L,"<="&EOMONTH(DATE(2026,8,1),0)) -> 0 | L36: =SUMIFS(컨설팅!H:H,컨설팅!L:L,">="&DATE(2026,9,1),컨설팅!L:L,"<="&EOMONTH(DATE(2026,9,1),0)) -> 0 | M36: =SUMIFS(컨설팅!H:H,컨설팅!L:L,">="&DATE(2026,10,1),컨설팅!L:L,"<="&EOMONTH(DATE(2026,10,1),0)) -> 0 | N36: =SUMIFS(컨설팅!H:H,컨설팅!L:L,">="&DATE(2026,11,1),컨설팅!L:L,"<="&EOMONTH(DATE(2026,11,1),0)) -> 0 | O36: =SUMIFS(컨설팅!H:H,컨설팅!L:L,">="&DATE(2026,12,1),컨설팅!L:L,"<="&EOMONTH(DATE(2026,12,1),0)) -> 0 | P36: =SUM(D36:O36) -> 2897704640
C37: 기술자문료 | D37: =SUMIFS(기술자문료!G:G,기술자문료!K:K,">="&DATE(2026,1,1),기술자문료!K:K,"<="&EOMONTH(DATE(2026,1,1),0)) -> 16130000 | E37: =SUMIFS(기술자문료!G:G,기술자문료!K:K,">="&DATE(2026,2,1),기술자문료!K:K,"<="&EOMONTH(DATE(2026,2,1),0)) -> 18500000 | F37: =SUMIFS(기술자문료!G:G,기술자문료!K:K,">="&DATE(2026,3,1),기술자문료!K:K,"<="&EOMONTH(DATE(2026,3,1),0)) -> 0 | G37: =SUMIFS(기술자문료!G:G,기술자문료!K:K,">="&DATE(2026,4,1),기술자문료!K:K,"<="&EOMONTH(DATE(2026,4,1),0)) -> 23372000 | H37: =SUMIFS(기술자문료!G:G,기술자문료!K:K,">="&DATE(2026,5,1),기술자문료!K:K,"<="&EOMONTH(DATE(2026,5,1),0)) -> 168693500 | I37: =SUMIFS(기술자문료!G:G,기술자문료!K:K,">="&DATE(2026,6,1),기술자문료!K:K,"<="&EOMONTH(DATE(2026,7,1),0)) -> 0 | J37: =SUMIFS(기술자문료!G:G,기술자문료!K:K,">="&DATE(2026,7,1),기술자문료!K:K,"<="&EOMONTH(DATE(2026,7,1),0)) -> 0 | K37: =SUMIFS(기술자문료!G:G,기술자문료!K:K,">="&DATE(2026,8,1),기술자문료!K:K,"<="&EOMONTH(DATE(2026,8,1),0)) -> 0 | L37: =SUMIFS(기술자문료!G:G,기술자문료!K:K,">="&DATE(2026,9,1),기술자문료!K:K,"<="&EOMONTH(DATE(2026,9,1),0)) -> 0 | M37: =SUMIFS(기술자문료!G:G,기술자문료!K:K,">="&DATE(2026,10,1),기술자문료!K:K,"<="&EOMONTH(DATE(2026,10,1),0)) -> 0 | N37: =SUMIFS(기술자문료!G:G,기술자문료!K:K,">="&DATE(2026,11,1),기술자문료!K:K,"<="&EOMONTH(DATE(2026,11,1),0)) -> 0 | O37: =SUMIFS(기술자문료!G:G,기술자문료!K:K,">="&DATE(2026,12,1),기술자문료!K:K,"<="&EOMONTH(DATE(2026,12,1),0)) -> 0 | P37: =SUM(D37:O37) -> 226695500
C38: 특허료 | D38: =SUMIFS(특허료!I:I,특허료!K:K,">="&DATE(2026,1,1),특허료!K:K,"<="&EOMONTH(DATE(2026,1,1),0)) -> 10389700 | E38: =SUMIFS(특허료!I:I,특허료!K:K,">="&DATE(2026,2,1),특허료!K:K,"<="&EOMONTH(DATE(2026,2,1),0)) -> 1206700 | F38: =SUMIFS(특허료!I:I,특허료!K:K,">="&DATE(2026,3,1),특허료!K:K,"<="&EOMONTH(DATE(2026,3,1),0)) -> 5791250 | G38: =SUMIFS(특허료!I:I,특허료!K:K,">="&DATE(2026,4,1),특허료!K:K,"<="&EOMONTH(DATE(2026,4,1),0)) -> 4160100 | H38: =SUMIFS(특허료!I:I,특허료!K:K,">="&DATE(2026,5,1),특허료!K:K,"<="&EOMONTH(DATE(2026,5,1),0)) -> 33145957 | I38: =SUMIFS(특허료!I:I,특허료!K:K,">="&DATE(2026,6,1),특허료!K:K,"<="&EOMONTH(DATE(2026,6,1),0)) -> 359200 | J38: =SUMIFS(특허료!I:I,특허료!K:K,">="&DATE(2026,7,1),특허료!K:K,"<="&EOMONTH(DATE(2026,7,1),0)) -> 0 | K38: =SUMIFS(특허료!I:I,특허료!K:K,">="&DATE(2026,8,1),특허료!K:K,"<="&EOMONTH(DATE(2026,8,1),0)) -> 0 | L38: =SUMIFS(특허료!I:I,특허료!K:K,">="&DATE(2026,9,1),특허료!K:K,"<="&EOMONTH(DATE(2026,9,1),0)) -> 0 | M38: =SUMIFS(특허료!I:I,특허료!K:K,">="&DATE(2026,10,1),특허료!K:K,"<="&EOMONTH(DATE(2026,10,1),0)) -> 0 | N38: =SUMIFS(특허료!I:I,특허료!K:K,">="&DATE(2026,11,1),특허료!K:K,"<="&EOMONTH(DATE(2026,11,1),0)) -> 0 | O38: =SUMIFS(특허료!I:I,특허료!K:K,">="&DATE(2026,12,1),특허료!K:K,"<="&EOMONTH(DATE(2026,12,1),0)) -> 0 | P38: =SUM(D38:O38) -> 55052907
C39: 자재판매 | D39: =SUMIFS(자재판매!P:P,자재판매!A:A,"2026-01*") -> 179887520 | E39: =SUMIFS(자재판매!P:P,자재판매!A:A,"2026-02*") -> 163409173 | F39: =SUMIFS(자재판매!P:P,자재판매!A:A,"2026-03*") -> 984722100 | G39: =SUMIFS(자재판매!P:P,자재판매!A:A,"2026-04*") -> 1349605250 | H39: =SUMIFS(자재판매!P:P,자재판매!A:A,"2026-05*") -> 1369349755 | I39: =SUMIFS(자재판매!P:P,자재판매!A:A,"2026-06*") -> 74643800 | J39: =SUMIFS(자재판매!P:P,자재판매!A:A,"2026-07*") -> 0 | K39: =SUMIFS(자재판매!P:P,자재판매!A:A,"2026-08*") -> 0 | L39: =SUMIFS(자재판매!P:P,자재판매!A:A,"2026-09*") -> 0 | M39: =SUMIFS(자재판매!P:P,자재판매!A:A,"2026-10*") -> 0 | N39: =SUMIFS(자재판매!P:P,자재판매!A:A,"2026-11*") -> 0 | O39: =SUMIFS(자재판매!P:P,자재판매!A:A,"2026-12*") -> 0 | P39: =SUM(D39:O39) -> 4121617598
C40: 그로홈 | D40: 39599779 | E40: 44422582 | F40: 48634554 | G40: 55236636 | P40: =SUM(D40:O40) -> 187893551
C41: 포어스토어 | D41: 3233074 | E41: 13117229 | F41: 43580016 | G41: 46841258 | P41: =SUM(D41:O41) -> 106771577
C42: 모여라딜 | D42: 208218 | E42: 0 | F42: -458482 | G42: 88645 | P42: =SUM(D42:O42) -> -161619
C43: 월합계 | D43: =SUM(D36:D42) -> 309083291 | E43: =SUM(E36:E42) -> 249691684 | F43: =SUM(F36:F42) -> 1672984738 | G43: =SUM(G36:G42) -> 2603006539 | H43: =SUM(H36:H42) -> 2.5493092e+09 | I43: =SUM(I36:I42) -> 211498750 | J43: =SUM(J36:J42) -> 0 | K43: =SUM(K36:K42) -> 0 | ... P43: =SUM(P36:P42) -> 7.5955742e+09

Sheet 컨설팅
B1: 순번 | C1: 매출구분 | D1: 업체명 | E1: 현장명 | F1: 총실행가 | G1: 계약금액(V-) | H1: 매출금액(v-) | I1: 구분 | J1: 계약일 | K1: 착공일 | L1: 매출일 | M1: 입금예정일 | N1: 입금일 | O1: 입금액(V+) | P1: 수금예정액(V+) | Q1: 준공일 | R1: 정산소요일 | S1: 입금지연 | T1: 자재판매 | U1: 컨설팅 순이익금 | V1: 이익률 | X1: 현장 소장 | Y1: 단가 | Z1: 노임 금액 | AB1: 추가노무비 | AC1: 안전관리비 | AD1: 장비대금 | AE1: 폐기물 | AF1: 기타 | AG1: 차감총액
B2: 1 | C2: 컨설팅현장 | D2: (주)부영씨엔씨 | E2: 탑마을타워빌 | F2: 425790000 | G2: 311676000 | H2: 91762800 | I2: 선금 | K2: 45950 | L2: 45947 | N2: 46092 | O2: =H2*1.1 -> 1.0093908e+08 | P2: =IF(L2="", 0, (H2*1.1)-O2) -> 0 | Q2: =Q4 -> 46094 | S2: =IF(OR(L2="",P2=0),"",IF(I2="선금",IF(TODAY()-L2>=91,"장기미수",IF(TODAY()-L2>=21,"관리","")),IF(TODAY()-L2>=91,"장기미수",IF(TODAY()-L2>=31,"관리","")))) | U2: =G2-T2-AG2 -> 258800140 | V2: =U2/F2 -> 0.60781169 | X2: 이성수 | Y2: 13000 | Z2: 59605000 | AB2: 27050000 | AD2: 2600000 | AE2: 3600000 | AF2: 19625860 | AG2: =SUM(AB2:AF2) -> 52875860
B3: 1 | C3: =C2 -> 컨설팅현장 | D3: =D2 -> (주)부영씨엔씨 | E3: =E2 -> 탑마을타워빌 | H3: 91762800 | I3: 중도금 | K3: =K2 -> 45950 | L3: 45976 | N3: 2026-04-20/29 | O3: =H3*1.1 -> 1.0093908e+08 | P3: =IF(L3="", 0, (H3*1.1)-O3) -> 0 | Q3: =Q4 -> 46094 | S3: =IF(OR(L3="",P3=0),"",IF(I3="선금",IF(TODAY()-L3>=91,"장기미수",IF(TODAY()-L3>=21,"관리","")),IF(TODAY()-L3>=91,"장기미수",IF(TODAY()-L3>=31,"관리","")))) | X3: 신현섭/윤성환 | Y3: 13000 | Z3: 54509000
B4: 1 | C4: =C3 -> 컨설팅현장 | D4: =D3 -> (주)부영씨엔씨 | E4: =E3 -> 탑마을타워빌 | G4: =-AG2 -> -52875860 | H4: =(G2-H2-H3)-AG2 -> 75274540 | I4: 잔금 | J4: 45992 | K4: =K3 -> 45950 | L4: 46171 | P4: =IF(L4="", 0, (H4*1.1)-O4) -> 82801994 | Q4: 46094 | S4: =IF(OR(L4="",P4=0),"",IF(I4="선금",IF(TODAY()-L4>=91,"장기미수",IF(TODAY()-L4>=21,"관리","")),IF(TODAY()-L4>=91,"장기미수",IF(TODAY()-L4>=31,"관리",""))))
B5: =IF(I4="잔금", B4+1, B4) -> 2 | C5: 컨설팅현장 | D5: (주)석민이앤씨 | E5: 아시아선수촌 | F5: 430000000 | G5: 292310000 | H5: 52342000 | I5: 선금 | K5: 45912 | L5: 45932 | N5: 45945 | Q5: =Q7 -> 46010 | S5: =IF(OR(L5="",P5=0),"",IF(I5="선금",IF(TODAY()-L5>=91,"장기미수",IF(TODAY()-L5>=21,"관리","")),IF(TODAY()-L5>=91,"장기미수",IF(TODAY()-L5>=31,"관리","")))) | U5: =G5-180715300-AG5 -> 35945700 | V5: =U5/F5 -> 0.083594651 | X5: 이준경 | Y5: 12000 | Z5: 141660000 | AB5: 11260000 | AE5: 350000 | AF5: 64039000 | AG5: =SUM(AB5:AF5) -> 75649000
B6: =IF(I5="잔금", B5+1, B5) -> 2 | C6: =C5 -> 컨설팅현장 | D6: =D5 -> (주)석민이앤씨 | E6: =E5 -> 아시아선수촌 | H6: 104684000 | I6: 중도금 | K6: =K5 -> 45912 | L6: 45975 | N6: 46006 | Q6: =Q7 -> 46010 | S6: =IF(OR(L6="",P6=0),"",IF(I6="선금",IF(TODAY()-L6>=91,"장기미수",IF(TODAY()-L6>=21,"관리","")),IF(TODAY()-L6>=91,"장기미수",IF(TODAY()-L6>=31,"관리","")))) | X6: 장진호 | Z6: 26630000
B7: =IF(I6="잔금", B6+1, B6) -> 2 | C7: =C6 -> 컨설팅현장 | D7: =D6 -> (주)석민이앤씨 | E7: =E6 -> 아시아선수촌 | G7: =-AG5 -> -75649000 | H7: =G5-H5-H6+G7 -> 59635000 | I7: 잔금 | J7: 45992 | K7: =K6 -> 45912 | L7: 46038 | M7: =IF(L7<>"", L7+30, "") -> 46068 | N7: 46066 | O7: =H7*1.1 -> 65598500 | P7: =IF(L7="", 0, (H7*1.1)-O7) -> 0 | Q7: 46010 | R7: =N7-Q7 -> 56 | S7: =IF(OR(L7="",P7=0),"",IF(I7="선금",IF(TODAY()-L7>=91,"장기미수",IF(TODAY()-L7>=21,"관리","")),IF(TODAY()-L7>=91,"장기미수",IF(TODAY()-L7>=31,"관리",""))))
B8: =IF(I7="잔금", B7+1, B7) -> 3 | C8: 컨설팅현장 | D8: (주)이음건설 | E8: 행원마을동아솔레시티 | F8: 450000000 | G8: =F8-Z8 -> 272578000 | H8: 54515600 | I8: 선금 | K8: 45961 | L8: 45964 | N8: 45970 | O8: =54515600*1.1 -> 59967160 | P8: =IF(L8="", 0, (H8*1.1)-O8) -> 0 | Q8: =Q10 -> 46133 | S8: =IF(OR(L8="",P8=0),"",IF(I8="선금",IF(TODAY()-L8>=91,"장기미수",IF(TODAY()-L8>=21,"관리","")),IF(TODAY()-L8>=91,"장기미수",IF(TODAY()-L8>=31,"관리","")))) | T8: 158539700 | U8: =G8-T8-AG8 -> 92712300 | V8: =U8/F8 -> 0.20602733 | X8: 조종억 | Y8: 19000 | Z8: 177422000 | AB8: 18676000 | AE8: 2650000 | AG8: =SUM(AB8:AF8) -> 21326000
B9: =IF(I8="잔금", B8+1, B8) -> 3 | C9: =C8 -> 컨설팅현장 | D9: =D8 -> (주)이음건설 | E9: =E8 -> 행원마을동아솔레시티 | H9: 109031200 | I9: 중도금 | J9: 45992 | K9: =K8 -> 45961 | L9: 46111 | M9: =IF(L9<>"", L9+30, "") -> 46141 | N9: 46127 | O9: =H9*1.1 -> 1.1993432e+08 | P9: =IF(L9="", 0, (H9*1.1)-O9) -> 0 | Q9: =Q10 -> 46133 | S9: =IF(OR(L9="",P9=0),"",IF(I9="선금",IF(TODAY()-L9>=91,"장기미수",IF(TODAY()-L9>=21,"관리","")),IF(TODAY()-L9>=91,"장기미수",IF(TODAY()-L9>=31,"관리",""))))
B10: =IF(I9="잔금", B9+1, B9) -> 3 | C10: =C9 -> 컨설팅현장 | D10: =D9 -> (주)이음건설 | E10: =E9 -> 행원마을동아솔레시티 | G10: =-AG8 -> -21326000 | H10: =G8-H8-H9-AG8 -> 87705200 | I10: 잔금 | J10: 45992 | K10: =K9 -> 45961 | L10: 46141 | M10: =IF(L10<>"", L10+30, "") -> 46171 | P10: =IF(L10="", 0, (H10*1.1)-O10) -> 96475720 | Q10: 46133 | S10: =IF(OR(L10="",P10=0),"",IF(I10="선금",IF(TODAY()-L10>=91,"장기미수",IF(TODAY()-L10>=21,"관리","")),IF(TODAY()-L10>=91,"장기미수",IF(TODAY()-L10>=31,"관리","")))) -> 관리
B11: =IF(I10="잔금", B10+1, B10) -> 4 | C11: 컨설팅현장 | D11: (주)석민이앤씨 | E11: 강서힐스테이트 | F11: 114700000 | G11: 59588500 | H11: 11917700 | I11: 선금 | K11: 45981 | L11: 45979 | N11: 45989 | O11: =H11*1.1 -> 13109470 | P11: =IF(L11="", 0, (H11*1.1)-O11) -> 0 | Q11: =Q13 -> 46113 | S11: =IF(OR(L11="",P11=0),"",IF(I11="선금",IF(TODAY()-L11>=91,"장기미수",IF(TODAY()-L11>=21,"관리","")),IF(TODAY()-L11>=91,"장기미수",IF(TODAY()-L11>=31,"관리","")))) | T11: 60795200 | U11: =G11-T11-AG11 -> -4804200 | V11: =U11/F11 -> -0.041884917 | X11: 이성수 | Y11: 18500 | Z11: 55111500 | AB11: 2147500 | AD11: 1450000 | AG11: =SUM(AB11:AF11) -> 3597500
B12: =IF(I11="잔금", B11+1, B11) -> 4 | C12: =C11 -> 컨설팅현장 | D12: =D11 -> (주)석민이앤씨 | E12: =E11 -> 강서힐스테이트 | H12: =G11*40% -> 23835400 | I12: 중도금 | J12: 45992 | K12: =K11 -> 45981 | L12: 46104 | M12: =IF(L12<>"", L12+30, "") -> 46134 | N12: 46127 | O12: =H12*1.1 -> 26218940 | P12: =IF(L12="", 0, (H12*1.1)-O12) -> 0 | Q12: =Q13 -> 46113 | S12: =IF(OR(L12="",P12=0),"",IF(I12="선금",IF(TODAY()-L12>=91,"장기미수",IF(TODAY()-L12>=21,"관리","")),IF(TODAY()-L12>=91,"장기미수",IF(TODAY()-L12>=31,"관리",""))))
B13: =IF(I12="잔금", B12+1, B12) -> 4 | C13: =C12 -> 컨설팅현장 | D13: =D12 -> (주)석민이앤씨 | E13: =E12 -> 강서힐스테이트 | G13: =-AG11 -> -3597500 | H13: =(G11*40%)-AG11 -> 20237900 | I13: 잔금 | J13: 45992 | K13: =K12 -> 45981 | L13: 46120 | M13: =IF(L13<>"", L13+30, "") -> 46150 | N13: 46171 | O13: =H13*1.1 -> 22261690 | P13: =IF(L13="", 0, (H13*1.1)-O13) -> 0 | Q13: 46113 | R13: =N13-Q13 -> 58 | S13: =IF(OR(L13="",P13=0),"",IF(I13="선금",IF(TODAY()-L13>=91,"장기미수",IF(TODAY()-L13>=21,"관리","")),IF(TODAY()-L13>=91,"장기미수",IF(TODAY()-L13>=31,"관리",""))))
B14: =IF(I13="잔금", B13+1, B13) -> 5 | C14: 컨설팅현장 | D14: 여름건설㈜ | E14: 원불교안암교당 | F14: 46890000 | G14: =F14-Z14 -> 41640000 | H14: 14756000 | I14: 선금 | K14: 45987 | L14: 45988 | N14: 45989 | O14: =H14*1.1 -> 16231600 | P14: =IF(L14="", 0, (H14*1.1)-O14) -> 0 | Q14: =Q16 -> 46095 | S14: =IF(OR(L14="",P14=0),"",IF(I14="선금",IF(TODAY()-L14>=91,"장기미수",IF(TODAY()-L14>=21,"관리","")),IF(TODAY()-L14>=91,"장기미수",IF(TODAY()-L14>=31,"관리","")))) | T14: 6151500 | U14: =G14-T14-AG14 -> 7688500 | V14: =U14/F14 -> 0.16396886 | X14: 조병철/조재부 | Y14: 14000 | Z14: 5250000 | AB14: 21000000 | AD14: 3000000 | AE14: 100000 | AF14: =1700000+2000000 -> 3700000 | AG14: =SUM(AB14:AF14) -> 27800000
B15: =IF(I14="잔금", B14+1, B14) -> 5 | C15: =C14 -> 컨설팅현장 | D15: =D14 -> 여름건설㈜ | E15: =E14 -> 원불교안암교당 | I15: 중도금 | K15: =K14 -> 45987 | P15: =IF(L15="", 0, (H15*1.1)-O15) -> 0 | Q15: =Q16 -> 46095 | S15: =IF(OR(L15="",P15=0),"",IF(I15="선금",IF(TODAY()-L15>=91,"장기미수",IF(TODAY()-L15>=21,"관리","")),IF(TODAY()-L15>=91,"장기미수",IF(TODAY()-L15>=31,"관리","")))) | X15: 손영구(재도장)
B16: =IF(I15="잔금", B15+1, B15) -> 5 | C16: =C15 -> 컨설팅현장 | D16: =D15 -> 여름건설㈜ | E16: =E15 -> 원불교안암교당 | G16: =-AG14 -> -27800000 | H16: =F14-H14-Z14-AG14 -> -916000 | I16: 잔금 | J16: 45992 | K16: =K15 -> 45987 | L16: 46133 | N16: 46133 | O16: -1007600 | P16: =IF(L16="", 0, (H16*1.1)-O16) -> -1.1641532e-10 | Q16: 46095 | R16: =N16-Q16 -> 38 | S16: =IF(OR(L16="",P16=0),"",IF(I16="선금",IF(TODAY()-L16>=91,"장기미수",IF(TODAY()-L16>=21,"관리","")),IF(TODAY()-L16>=91,"장기미수",IF(TODAY()-L16>=31,"관리","")))) -> 관리
B17: =IF(I16="잔금", B16+1, B16) -> 6 | C17: 컨설팅현장 | D17: 신화건설㈜ | E17: 광명노온정수장 | F17: 14500000 | G17: 10336000 | I17: 선금 | K17: 46000 | P17: =IF(L17="", 0, (H17*1.1)-O17) -> 0 | Q17: =Q19 -> 46080 | S17: =IF(OR(L17="",P17=0),"",IF(I17="선금",IF(TODAY()-L17>=91,"장기미수",IF(TODAY()-L17>=21,"관리","")),IF(TODAY()-L17>=91,"장기미수",IF(TODAY()-L17>=31,"관리","")))) | T17: 8440100 | U17: =G17-T17-AG17 -> 595900 | V17: =U17/F17 -> 0.041096552 | X17: 정상혁 | Y17: 12000 | Z17: 4164000 | AB17: 750000 | AD17: 400000 | AE17: =130000+20000 -> 150000 | AG17: =SUM(AB17:AF17) -> 1300000
B18: =IF(I17="잔금", B17+1, B17) -> 6 | C18: =C17 -> 컨설팅현장 | D18: =D17 -> 신화건설㈜ | E18: =E17 -> 광명노온정수장 | I18: 중도금 | K18: =K17 -> 46000 | P18: =IF(L18="", 0, (H18*1.1)-O18) -> 0 | Q18: =Q19 -> 46080 | S18: =IF(OR(L18="",P18=0),"",IF(I18="선금",IF(TODAY()-L18>=91,"장기미수",IF(TODAY()-L18>=21,"관리","")),IF(TODAY()-L18>=91,"장기미수",IF(TODAY()-L18>=31,"관리",""))))
B19: =IF(I18="잔금", B18+1, B18) -> 6 | C19: =C18 -> 컨설팅현장 | D19: =D18 -> 신화건설㈜ | E19: =E18 -> 광명노온정수장 | G19: =-AG17 -> -1300000 | H19: =(G17)-AG17 -> 9036000 | I19: 잔금 | J19: 45992 | K19: =K18 -> 46000 | L19: 46080 | M19: =IF(L19<>"", L19+30, "") -> 46110 | N19: 46112 | O19: =H19*1.1 -> 9939600 | P19: =IF(L19="", 0, (H19*1.1)-O19) -> 0 | Q19: 46080 | R19: =N19-Q19 -> 32 | S19: =IF(OR(L19="",P19=0),"",IF(I19="선금",IF(TODAY()-L19>=91,"장기미수",IF(TODAY()-L19>=21,"관리","")),IF(TODAY()-L19>=91,"장기미수",IF(TODAY()-L19>=31,"관리",""))))
B20: =IF(I19="잔금", B19+1, B19) -> 7 | C20: 컨설팅현장 | D20: (주)에이치제이건설 | E20: 해운대센텀트루엘 | F20: 89000000 | G20: =F20-Z20 -> 55577000 | H20: =G20*20% -> 11115400 | I20: 선금 | J20: 46084 | K20: 46085 | L20: 46085 | M20: =IF(L20<>"", L20+20, "") -> 46105 | N20: 46118 | O20: =H20*1.1 -> 12226940 | P20: =IF(L20="", 0, (H20*1.1)-O20) -> 0 | Q20: =Q22 -> 46144 | S20: =IF(OR(L20="",P20=0),"",IF(I20="선금",IF(TODAY()-L20>=91,"장기미수",IF(TODAY()-L20>=21,"관리","")),IF(TODAY()-L20>=91,"장기미수",IF(TODAY()-L20>=31,"관리","")))) | U20: =G20-T20-AG20 -> 54777000 | V20: =U20/F20 -> 0.61547191 | X20: 김용진 | Y20: 13000 | Z20: =2571*Y20 -> 33423000 | AE20: 800000 | AG20: =SUM(AB20:AF20) -> 800000
B21: =IF(I20="잔금", B20+1, B20) -> 7 | C21: =C20 -> 컨설팅현장 | D21: =D20 -> (주)에이치제이건설 | E21: =E20 -> 해운대센텀트루엘 | H21: =G20*40% -> 22230800 | I21: 중도금 | J21: =J20 -> 46084 | K21: =K20 -> 46085 | L21: 46115 | M21: =IF(L21<>"", L21+30, "") -> 46145 | N21: 46127 | O21: =H21*1.1 -> 24453880 | P21: =IF(L21="", 0, (H21*1.1)-O21) -> 0 | Q21: =Q22 -> 46144 | S21: =IF(OR(L21="",P21=0),"",IF(I21="선금",IF(TODAY()-L21>=91,"장기미수",IF(TODAY()-L21>=21,"관리","")),IF(TODAY()-L21>=91,"장기미수",IF(TODAY()-L21>=31,"관리",""))))
B22: =IF(I21="잔금", B21+1, B21) -> 7 | C22: =C21 -> 컨설팅현장 | D22: =D21 -> (주)에이치제이건설 | E22: =E21 -> 해운대센텀트루엘 | G22: =-AG20 -> -800000 | H22: =(G20*40%)-AG20 -> 21430800 | I22: 잔금 | J22: =J21 -> 46084 | K22: =K21 -> 46085 | L22: 46157 | M22: =IF(L22<>"", L22+30, "") -> 46187 | P22: =IF(L22="", 0, (H22*1.1)-O22) -> 23573880 | Q22: 46144 | S22: =IF(OR(L22="",P22=0),"",IF(I22="선금",IF(TODAY()-L22>=91,"장기미수",IF(TODAY()-L22>=21,"관리","")),IF(TODAY()-L22>=91,"장기미수",IF(TODAY()-L22>=31,"관리",""))))
B23: =IF(I22="잔금", B22+1, B22) -> 8 | C23: 컨설팅현장 | D23: 여름건설㈜ | E23: 자양10차현대홈타운 | F23: 30420000 | G23: =F23-Z23 -> 21771000 | H23: =G23*20% -> 4354200 | I23: 선금 | J23: 45999 | K23: 46098 | L23: 46099 | M23: =IF(L23<>"", L23+20, "") -> 46119 | N23: 46127 | O23: =H23*1.1 -> 4789620 | P23: =IF(L23="", 0, (H23*1.1)-O23) -> 0 | Q23: =Q25 -> 46105 | S23: =IF(OR(L23="",P23=0),"",IF(I23="선금",IF(TODAY()-L23>=91,"장기미수",IF(TODAY()-L23>=21,"관리","")),IF(TODAY()-L23>=91,"장기미수",IF(TODAY()-L23>=31,"관리","")))) | T23: 10983800 | U23: =G23-T23-AG23 -> 9611200 | V23: =U23/F23 -> 0.31595003 | X23: 윤정삼 | Y23: 12,000/15,000 | Z23: =(12000*107)+(12000*85)+(15000*423) -> 8649000 | AB23: 1076000 | AE23: 100000 | AG23: =SUM(AB23:AF23) -> 1176000
B24: =IF(I23="잔금", B23+1, B23) -> 8 | C24: 컨설팅현장 | D24: =D23 -> 여름건설㈜ | E24: =E23 -> 자양10차현대홈타운 | H24: =G23*40% -> 8708400 | I24: 중도금 | J24: =J23 -> 45999 | K24: =K23 -> 46098 | L24: 46104 | M24: =IF(L24<>"", L24+30, "") -> 46134 | N24: 46127 | O24: =H24*1.1 -> 9579240 | P24: =IF(L24="", 0, (H24*1.1)-O24) -> 0 | Q24: =Q25 -> 46105 | S24: =IF(OR(L24="",P24=0),"",IF(I24="선금",IF(TODAY()-L24>=91,"장기미수",IF(TODAY()-L24>=21,"관리","")),IF(TODAY()-L24>=91,"장기미수",IF(TODAY()-L24>=31,"관리",""))))
B25: =IF(I24="잔금", B24+1, B24) -> 8 | C25: 컨설팅현장 | D25: =D24 -> 여름건설㈜ | E25: =E24 -> 자양10차현대홈타운 | G25: =-AG23 -> -1176000 | H25: =(G23*40%)-AG23 -> 7532400 | I25: 잔금 | J25: =J24 -> 45999 | K25: =K24 -> 46098 | L25: 46126 | M25: =IF(L25<>"", L25+30, "") -> 46156 | N25: 46154 | O25: =H25*1.1 -> 8285640 | P25: =IF(L25="", 0, (H25*1.1)-O25) -> 0 | Q25: 46105 | R25: =N25-Q25 -> 49 | S25: =IF(OR(L25="",P25=0),"",IF(I25="선금",IF(TODAY()-L25>=91,"장기미수",IF(TODAY()-L25>=21,"관리","")),IF(TODAY()-L25>=91,"장기미수",IF(TODAY()-L25>=31,"관리",""))))
B26: =IF(I25="잔금", B25+1, B25) -> 9 | C26: 컨설팅현장 | D26: 여름건설㈜ | E26: 광덕파크빌 | F26: 39060000 | G26: =F26-Z26 -> 28884000 | H26: =G26*20% -> 5776800 | I26: 선금 | J26: 45999 | K26: 46149 | L26: 46156 | M26: =IF(L26<>"", L26+20, "") -> 46176 | P26: =IF(L26="", 0, (H26*1.1)-O26) -> 6354480 | Q26: =Q28 -> (예)2026-05-31 | S26: =IF(OR(L26="",P26=0),"",IF(I26="선금",IF(TODAY()-L26>=91,"장기미수",IF(TODAY()-L26>=21,"관리","")),IF(TODAY()-L26>=91,"장기미수",IF(TODAY()-L26>=31,"관리","")))) | X26: 김용재 | Y26: 12000 | Z26: =(632*12000)+(216*12000) -> 10176000 | AG26: =SUM(AB26:AF26) -> 0
B27: =IF(I26="잔금", B26+1, B26) -> 9 | C27: 컨설팅현장 | D27: =D26 -> 여름건설㈜ | E27: =E26 -> 광덕파크빌 | H27: =G26*40% -> 11553600 | I27: 중도금 | J27: =J26 -> 45999 | K27: =K26 -> 46149 | L27: 46160 | M27: =IF(L27<>"", L27+30, "") -> 46190 | P27: =IF(L27="", 0, (H27*1.1)-O27) -> 12708960 | Q27: =Q28 -> (예)2026-05-31 | S27: =IF(OR(L27="",P27=0),"",IF(I27="선금",IF(TODAY()-L27>=91,"장기미수",IF(TODAY()-L27>=21,"관리","")),IF(TODAY()-L27>=91,"장기미수",IF(TODAY()-L27>=31,"관리",""))))
B28: =IF(I27="잔금", B27+1, B27) -> 9 | C28: 컨설팅현장 | D28: =D27 -> 여름건설㈜ | E28: =E27 -> 광덕파크빌 | G28: =-AG26 -> 0 | H28: =(G26*40%)-AG26 -> 11553600 | I28: 잔금 | J28: =J27 -> 45999 | K28: =K26 -> 46149 | M28: =IF(L28<>"", L28+30, "") | P28: =IF(L28="", 0, (H28*1.1)-O28) -> 0 | Q28: (예)2026-05-31 | S28: =IF(OR(L28="",P28=0),"",IF(I28="선금",IF(TODAY()-L28>=91,"장기미수",IF(TODAY()-L28>=21,"관리","")),IF(TODAY()-L28>=91,"장기미수",IF(TODAY()-L28>=31,"관리",""))))
B29: =IF(I28="잔금", B28+1, B28) -> 10 | C29: 컨설팅현장 | D29: (주)기림이앤씨 | E29: 해누리선경 | F29: 202900000 | G29: =F29-AK29 -> 202900000 | H29: =G29*20% -> 40580000 | I29: 선금 | J29: 45999 | K29: 미정 | M29: =IF(L29<>"", L29+20, "") | P29: =IF(L29="", 0, (H29*1.1)-O29) -> 0 | Q29: =Q31 -> 미정 | S29: =IF(OR(L29="",P29=0),"",IF(I29="선금",IF(TODAY()-L29>=91,"장기미수",IF(TODAY()-L29>=21,"관리","")),IF(TODAY()-L29>=91,"장기미수",IF(TODAY()-L29>=31,"관리","")))) | Z29: 63670000 | AG29: =SUM(AB29:AF29) -> 0
B30: =IF(I29="잔금", B29+1, B29) -> 10 | C30: 컨설팅현장 | D30: =D29 -> (주)기림이앤씨 | E30: =E29 -> 해누리선경 | H30: =G29*40% -> 81160000 | I30: 중도금 | J30: =J29 -> 45999 | K30: =K29 -> 미정 | M30: =IF(L30<>"", L30+30, "") | P30: =IF(L30="", 0, (H30*1.1)-O30) -> 0 | Q30: =Q31 -> 미정 | S30: =IF(OR(L30="",P30=0),"",IF(I30="선금",IF(TODAY()-L30>=91,"장기미수",IF(TODAY()-L30>=21,"관리","")),IF(TODAY()-L30>=91,"장기미수",IF(TODAY()-L30>=31,"관리",""))))
B31: =IF(I30="잔금", B30+1, B30) -> 10 | C31: 컨설팅현장 | D31: =D30 -> (주)기림이앤씨 | E31: =E30 -> 해누리선경 | G31: =-AG29 -> 0 | H31: =(G29*40%)-AG29 -> 81160000 | I31: 잔금 | J31: =J30 -> 45999 | K31: =K30 -> 미정 | M31: =IF(L31<>"", L31+30, "") | P31: =IF(L31="", 0, (H31*1.1)-O31) -> 0 | Q31: 미정 | S31: =IF(OR(L31="",P31=0),"",IF(I31="선금",IF(TODAY()-L31>=91,"장기미수",IF(TODAY()-L31>=21,"관리","")),IF(TODAY()-L31>=91,"장기미수",IF(TODAY()-L31>=31,"관리",""))))
B32: =IF(I31="잔금", B31+1, B31) -> 11 | C32: 컨설팅현장 | D32: (주)기림이앤씨 | E32: 지웰시티푸르지오1단지오피스텔 | F32: 122600000 | G32: =F32-Z32 -> 86060000 | H32: =G32*20% -> 17212000 | I32: 선금 | J32: 45999 | K32: 46141 | L32: 46153 | M32: =IF(L32<>"", L32+20, "") -> 46173 | N32: 46157 | O32: =H32*1.1 -> 18933200 | P32: =IF(L32="", 0, (H32*1.1)-O32) -> 0 | Q32: =Q34 -> (예)2026-05-31 | S32: =IF(OR(L32="",P32=0),"",IF(I32="선금",IF(TODAY()-L32>=91,"장기미수",IF(TODAY()-L32>=21,"관리","")),IF(TODAY()-L32>=91,"장기미수",IF(TODAY()-L32>=31,"관리","")))) | X32: 김원규 | Y32: 14000 | Z32: =2610*14000 -> 36540000 | AG32: =SUM(AB32:AF32) -> 0
B33: =IF(I32="잔금", B32+1, B32) -> 11 | C33: 컨설팅현장 | D33: =D32 -> (주)기림이앤씨 | E33: =E32 -> 지웰시티푸르지오1단지오피스텔 | H33: =G32*40% -> 34424000 | I33: 중도금 | J33: =J32 -> 45999 | K33: =K32 -> 46141 | L33: 46157 | M33: =IF(L33<>"", L33+30, "") -> 46187 | P33: =IF(L33="", 0, (H33*1.1)-O33) -> 37866400 | Q33: =Q34 -> (예)2026-05-31 | S33: =IF(OR(L33="",P33=0),"",IF(I33="선금",IF(TODAY()-L33>=91,"장기미수",IF(TODAY()-L33>=21,"관리","")),IF(TODAY()-L33>=91,"장기미수",IF(TODAY()-L33>=31,"관리",""))))
B34: =IF(I33="잔금", B33+1, B33) -> 11 | C34: 컨설팅현장 | D34: =D33 -> (주)기림이앤씨 | E34: =E33 -> 지웰시티푸르지오1단지오피스텔 | G34: =-AG32 -> 0 | H34: =(G32*40%)-AG32 -> 34424000 | I34: 잔금 | J34: =J33 -> 45999 | K34: =K33 -> 46141 | M34: =IF(L34<>"", L34+30, "") | P34: =IF(L34="", 0, (H34*1.1)-O34) -> 0 | Q34: (예)2026-05-31 | S34: =IF(OR(L34="",P34=0),"",IF(I34="선금",IF(TODAY()-L34>=91,"장기미수",IF(TODAY()-L34>=21,"관리","")),IF(TODAY()-L34>=91,"장기미수",IF(TODAY()-L34>=31,"관리",""))))
B35: =IF(I34="잔금", B34+1, B34) -> 12 | C35: 컨설팅현장 | D35: 건진개발㈜ | E35: 덕천동롯데 | F35: 105000000 | G35: =F35-Z35 -> 61800000 | H35: 12360000 | I35: 선금 | J35: 45999 | K35: 46085 | L35: 46085 | M35: =IF(L35<>"", L35+20, "") -> 46105 | N35: 46086 | O35: =H35*1.1 -> 13596000 | P35: =IF(L35="", 0, (H35*1.1)-O35) -> 0 | Q35: =Q37 -> 46148 | S35: =IF(OR(L35="",P35=0),"",IF(I35="선금",IF(TODAY()-L35>=91,"장기미수",IF(TODAY()-L35>=21,"관리","")),IF(TODAY()-L35>=91,"장기미수",IF(TODAY()-L35>=31,"관리","")))) | X35: 박성은 | Y35: 15000 | Z35: =2880*15000 -> 43200000 | AB35: 5880000 | AE35: 800000 | AG35: =SUM(AB35:AF35) -> 6680000
B36: =IF(I35="잔금", B35+1, B35) -> 12 | C36: 컨설팅현장 | D36: =D35 -> 건진개발㈜ | E36: =E35 -> 덕천동롯데 | H36: 24720000 | I36: 중도금 | J36: =J35 -> 45999 | K36: =K35 -> 46085 | L36: 46139 | M36: =IF(L36<>"", L36+30, "") -> 46169 | N36: 46148 | O36: =H36*1.1 -> 27192000 | P36: =IF(L36="", 0, (H36*1.1)-O36) -> 0 | Q36: =Q37 -> 46148 | S36: =IF(OR(L36="",P36=0),"",IF(I36="선금",IF(TODAY()-L36>=91,"장기미수",IF(TODAY()-L36>=21,"관리","")),IF(TODAY()-L36>=91,"장기미수",IF(TODAY()-L36>=31,"관리",""))))
B37: =IF(I36="잔금", B36+1, B36) -> 12 | C37: 컨설팅현장 | D37: =D36 -> 건진개발㈜ | E37: =E36 -> 덕천동롯데 | G37: =-AG35 -> -6680000 | H37: =(G35*40%)-AG35 -> 18040000 | I37: 잔금 | J37: =J36 -> 45999 | K37: =K36 -> 46085 | L37: 46161 | M37: =IF(L37<>"", L37+30, "") -> 46191 | N37: 46168 | O37: =H37*1.1 -> 19844000 | P37: =IF(L37="", 0, (H37*1.1)-O37) -> 0 | Q37: 46148 | S37: =IF(OR(L37="",P37=0),"",IF(I37="선금",IF(TODAY()-L37>=91,"장기미수",IF(TODAY()-L37>=21,"관리","")),IF(TODAY()-L37>=91,"장기미수",IF(TODAY()-L37>=31,"관리",""))))
B38: =IF(I37="잔금", B37+1, B37) -> 13 | C38: 컨설팅현장 | D38: (주)석민이앤씨 | E38: 동탄역시범한화꿈에그린프레스티지 | F38: 92100000 | G38: =F38-Z38 -> 68470000 | H38: =G38*20% -> 13694000 | I38: 선금 | J38: 45999 | K38: 46091 | L38: 46091 | M38: =IF(L38<>"", L38+20, "") -> 46111 | N38: 46094 | O38: =H38*1.1 -> 15063400 | P38: =IF(L38="", 0, (H38*1.1)-O38) -> 0 | Q38: =Q40 -> 46110 | S38: =IF(OR(L38="",P38=0),"",IF(I38="선금",IF(TODAY()-L38>=91,"장기미수",IF(TODAY()-L38>=21,"관리","")),IF(TODAY()-L38>=91,"장기미수",IF(TODAY()-L38>=31,"관리","")))) | T38: 39731750 | U38: =G38-T38-AG38 -> -26750 | V38: =U38/F38 -> -0.00029044517 | X38: 조병철/조재부 | Y38: 10000 | Z38: =2363*Y38 -> 23630000 | AB38: 28065000 | AE38: 700000 | AG38: =SUM(AB38:AF38) -> 28765000
B39: =IF(I38="잔금", B38+1, B38) -> 13 | C39: 컨설팅현장 | D39: =D38 -> (주)석민이앤씨 | E39: =E38 -> 동탄역시범한화꿈에그린프레스티지 | I39: 중도금 | J39: 45999 | K39: =K38 -> 46091 | M39: =IF(L39<>"", L39+30, "") | P39: =IF(L39="", 0, (H39*1.1)-O39) -> 0 | Q39: =Q40 -> 46110 | S39: =IF(OR(L39="",P39=0),"",IF(I39="선금",IF(TODAY()-L39>=91,"장기미수",IF(TODAY()-L39>=21,"관리","")),IF(TODAY()-L39>=91,"장기미수",IF(TODAY()-L39>=31,"관리",""))))
B40: =IF(I39="잔금", B39+1, B39) -> 13 | C40: 컨설팅현장 | D40: =D39 -> (주)석민이앤씨 | E40: =E39 -> 동탄역시범한화꿈에그린프레스티지 | G40: =-AG38 -> -28765000 | H40: =(G38*80%)-AG38 -> 26011000 | I40: 잔금 | J40: 45999 | K40: =K39 -> 46091 | L40: 46118 | M40: =IF(L40<>"", L40+30, "") -> 46148 | N40: 46171 | O40: =H40*1.1 -> 28612100 | P40: =IF(L40="", 0, (H40*1.1)-O40) -> 0 | Q40: 46110 | R40: =N40-Q40 -> 61 | S40: =IF(OR(L40="",P40=0),"",IF(I40="선금",IF(TODAY()-L40>=91,"장기미수",IF(TODAY()-L40>=21,"관리","")),IF(TODAY()-L40>=91,"장기미수",IF(TODAY()-L40>=31,"관리",""))))
...

Sheet 기술자문료
B1: 순번 | C1: 매출구분 | D1: 업체명 | E1: 현장명 | F1: 계약금액(V-) | G1: 매출금액(v-) | H1: 구분 | I1: 계약일 | J1: 착공일 | K1: 매출일 | L1: 입금예정일 | M1: 입금일 | N1: 입금액(V+) | O1: 수금예정액(V+) | P1: 준공일 | Q1: 입금지연 | S1: 차감총액 | T1: 영업수수료 | V1: 예외여부 | W1: 예외사유
B2: 1 | C2: 기술자문료 | D2: (주)에이치제이건설 | E2: 해운대 센텀트루엘아파트(재도장) | F2: 133800000 | G2: =F2*20% -> 26760000 | H2: 선금 | J2: 45943 | K2: 45967 | L2: =IF(K2<>"", K2+30, "") -> 45997 | M2: 46142 | N2: =G2*1.1 -> 29436000 | O2: =IF(K2="", 0, (G2*1.1)-N2) -> 0 | P2: =P4 -> 46142 | Q2: =IF(OR(K2="",O2=0),"",IF(TODAY()-K2>=91,"장기미수",IF(TODAY()-K2>=31,"관리",""))) | T2: 38500000
B3: =IF(H2="잔금", B2+1, B2) -> 1 | C3: =C2 -> 기술자문료 | D3: =D2 -> (주)에이치제이건설 | E3: =E2 -> 해운대 센텀트루엘아파트(재도장) | G3: =F2*40% -> 53520000 | H3: 중도금 | J3: =J2 -> 45943 | K3: 46010 | L3: =IF(K3<>"", K3+30, "") -> 46040 | M3: 46171 | N3: =G3*1.1 -> 58872000 | O3: =IF(K3="", 0, (G3*1.1)-N3) -> 0 | P3: =P4 -> 46142 | Q3: =IF(OR(K3="",O3=0),"",IF(TODAY()-K3>=91,"장기미수",IF(TODAY()-K3>=31,"관리",""))) | T3: 38500000
B4: =IF(H3="잔금", B3+1, B3) -> 1 | C4: =C3 -> 기술자문료 | D4: =D3 -> (주)에이치제이건설 | E4: =E3 -> 해운대 센텀트루엘아파트(재도장) | G4: =F2-G2-G3-S4 -> 38970000 | H4: 잔금 | I4: 45992 | J4: =J3 -> 45943 | K4: 46155 | L4: =IF(K4<>"", K4+30, "") -> 46185 | O4: =IF(K4="", 0, (G4*1.1)-N4) -> 42867000 | P4: 46142 | Q4: =IF(OR(K4="",O4=0),"",IF(TODAY()-K4>=91,"장기미수",IF(TODAY()-K4>=31,"관리",""))) | S4: 14550000 | T4: =40700000+14300000+34100000 -> 89100000
B5: =IF(H4="잔금", B4+1, B4) -> 2 | C5: 기술자문료 | D5: ㈜대한진단건설 | E5: 해운대 센텀트루엘아파트(주차장) | F5: 77160000 | G5: =F5*20% -> 15432000 | H5: 선금 | I5: 46028 | J5: 46084 | K5: 46133 | L5: =IF(K5<>"", K5+30, "") -> 46163 | M5: 46142 | N5: =G5*1.1 -> 16975200 | O5: =IF(K5="", 0, (G5*1.1)-N5) -> 0 | P5: =P7 -> (예)2026-05-31 | Q5: =IF(OR(K5="",O5=0),"",IF(TODAY()-K5>=91,"장기미수",IF(TODAY()-K5>=31,"관리",""))) | T5: 22000000
B6: =IF(H5="잔금", B5+1, B5) -> 2 | C6: =C5 -> 기술자문료 | D6: =D5 -> ㈜대한진단건설 | E6: =E5 -> 해운대 센텀트루엘아파트(주차장) | G6: =F5*40% -> 30864000 | H6: 중도금 | I6: =I5 -> 46028 | J6: =J5 -> 46084 | O6: =IF(K6="", 0, (G6*1.1)-N6) -> 0 | P6: =P7 -> (예)2026-05-31 | Q6: =IF(OR(K6="",O6=0),"",IF(TODAY()-K6>=91,"장기미수",IF(TODAY()-K6>=31,"관리",""))) | T6: 28600000
B7: =IF(H6="잔금", B6+1, B6) -> 2 | C7: =C6 -> 기술자문료 | D7: =D6 -> ㈜대한진단건설 | E7: =E6 -> 해운대 센텀트루엘아파트(주차장) | G7: =(F5*40%)-S7 -> 30864000 | H7: 잔금 | I7: =I6 -> 46028 | J7: =J6 -> 46084 | O7: =IF(K7="", 0, (G7*1.1)-N7) -> 0 | P7: (예)2026-05-31 | Q7: =IF(OR(K7="",O7=0),"",IF(TODAY()-K7>=91,"장기미수",IF(TODAY()-K7>=31,"관리",""))) | T7: =19800000+19800000 -> 39600000
B8: =IF(H7="잔금", B7+1, B7) -> 3 | C8: 기술자문료 | D8: (주)에이치제이건설 | E8: 서면동일파크스위트3차아파트 | F8: 43260000 | G8: 16130000 | H8: 선금 | I8: 45992 | J8: 45978 | K8: 46027 | L8: =IF(K8<>"", K8+30, "") -> 46057 | M8: 46142 | N8: =G8*1.1 -> 17743000 | O8: =IF(K8="", 0, (G8*1.1)-N8) -> 0 | P8: =P10 -> 46142 | Q8: =IF(OR(K8="",O8=0),"",IF(TODAY()-K8>=91,"장기미수",IF(TODAY()-K8>=31,"관리",""))) | T8: 16500000 | X8: 11월 13일
B9: =IF(H8="잔금", B8+1, B8) -> 3 | C9: =C8 -> 기술자문료 | D9: =D8 -> (주)에이치제이건설 | E9: =E8 -> 서면동일파크스위트3차아파트 | G9: 11000000 | H9: 중도금 | I9: 45992 | J9: =J8 -> 45978 | K9: 46066 | L9: =IF(K9<>"", K9+30, "") -> 46096 | M9: 46157 | N9: =G9*1.1 -> 12100000 | O9: =IF(K9="", 0, (G9*1.1)-N9) -> 0 | P9: =P10 -> 46142 | Q9: =IF(OR(K9="",O9=0),"",IF(TODAY()-K9>=91,"장기미수",IF(TODAY()-K9>=31,"관리",""))) | T9: 16500000
B10: =IF(H9="잔금", B9+1, B9) -> 3 | C10: =C9 -> 기술자문료 | D10: =D9 -> (주)에이치제이건설 | E10: =E9 -> 서면동일파크스위트3차아파트 | G10: =F8-G8-G9-S10 -> 13660000 | H10: 잔금 | I10: 45992 | J10: =J9 -> 45978 | K10: 46153 | L10: =IF(K10<>"", K10+30, "") -> 46183 | O10: =IF(K10="", 0, (G10*1.1)-N10) -> 15026000 | P10: 46142 | Q10: =IF(OR(K10="",O10=0),"",IF(TODAY()-K10>=91,"장기미수",IF(TODAY()-K10>=31,"관리",""))) | S10: 2470000 | T10: 19800000
B11: =IF(H10="잔금", B10+1, B10) -> 4 | C11: 기술자문료 | D11: (주)청명이앤디 | E11: 영주동도경오벨리스아파트 | F11: 15000000 | G11: =F11*50% -> 7500000 | H11: 선금 | I11: 46000 | J11: 45999 | K11: 46058 | L11: 46088 | M11: 46073 | N11: =G11*1.1 -> 8250000 | O11: =IF(K11="", 0, (G11*1.1)-N11) -> 0 | P11: =P13 -> 46134 | Q11: =IF(OR(K11="",O11=0),"",IF(TODAY()-K11>=91,"장기미수",IF(TODAY()-K11>=31,"관리",""))) | V11: Y | W11: 영업수수료
B12: =IF(H11="잔금", B11+1, B11) -> 4 | C12: =C11 -> 기술자문료 | D12: =D11 -> (주)청명이앤디 | E12: =E11 -> 영주동도경오벨리스아파트 | H12: 중도금 | I12: =I11 -> 46000 | J12: =J11 -> 45999 | O12: =IF(K12="", 0, (G12*1.1)-N12) -> 0 | P12: =P13 -> 46134 | Q12: =IF(OR(K12="",O12=0),"",IF(TODAY()-K12>=91,"장기미수",IF(TODAY()-K12>=31,"관리","")))
B13: =IF(H12="잔금", B12+1, B12) -> 4 | C13: =C12 -> 기술자문료 | D13: =D12 -> (주)청명이앤디 | E13: =E12 -> 영주동도경오벨리스아파트 | G13: =(F11*50%)-S13 -> 7500000 | H13: 잔금 | I13: =I12 -> 46000 | J13: =J12 -> 45999 | K13: 46155 | L13: =IF(K13<>"", K13+30, "") -> 46185 | M13: 46164 | N13: =G13*1.1 -> 8250000 | O13: =IF(K13="", 0, (G13*1.1)-N13) -> 0 | P13: 46134 | Q13: =IF(OR(K13="",O13=0),"",IF(TODAY()-K13>=91,"장기미수",IF(TODAY()-K13>=31,"관리",""))) | T13: 16500000
B14: =IF(H13="잔금", B13+1, B13) -> 5 | C14: 기술자문료 | D14: (주)에이치제이건설 | E14: 양산평산KCC스위첸 | F14: 55000000 | H14: 선금 | J14: 45589 | O14: =IF(K14="", 0, (G14*1.1)-N14) -> 0 | P14: =P16 -> 45900 | Q14: =IF(OR(K14="",O14=0),"",IF(TODAY()-K14>=91,"장기미수",IF(TODAY()-K14>=31,"관리",""))) | X14: 11월 13일
B15: =IF(H14="잔금", B14+1, B14) -> 5 | C15: =C14 -> 기술자문료 | D15: =D14 -> (주)에이치제이건설 | E15: =E14 -> 양산평산KCC스위첸 | H15: 중도금 | J15: =J14 -> 45589 | O15: =IF(K15="", 0, (G15*1.1)-N15) -> 0 | P15: =P16 -> 45900 | Q15: =IF(OR(K15="",O15=0),"",IF(TODAY()-K15>=91,"장기미수",IF(TODAY()-K15>=31,"관리","")))
B16: =IF(H15="잔금", B15+1, B15) -> 5 | C16: =C15 -> 기술자문료 | D16: =D15 -> (주)에이치제이건설 | E16: =E15 -> 양산평산KCC스위첸 | G16: =F14-S16 -> 55000000 | H16: 잔금 | I16: 45992 | J16: =J15 -> 45589 | O16: =IF(K16="", 0, (G16*1.1)-N16) -> 0 | P16: 45900 | Q16: =IF(OR(K16="",O16=0),"",IF(TODAY()-K16>=91,"장기미수",IF(TODAY()-K16>=31,"관리",""))) | T16: 97900000
B17: =IF(H16="잔금", B16+1, B16) -> 6 | C17: 기술자문료_s | D17: (주)부영씨엔씨 | E17: 잠실리센츠 | F17: 406800000 | H17: 선금 | J17: 45966 | O17: =IF(K17="", 0, (G17*1.1)-N17) -> 0 | P17: =P19 -> (예)2026-05-31 | Q17: =IF(OR(K17="",O17=0),"",IF(TODAY()-K17>=91,"장기미수",IF(TODAY()-K17>=31,"관리",""))) | X17: 11월 10일
B18: =IF(H17="잔금", B17+1, B17) -> 6 | C18: =C17 -> 기술자문료_s | D18: =D17 -> (주)부영씨엔씨 | E18: =E17 -> 잠실리센츠 | H18: 중도금 | J18: =J17 -> 45966 | O18: =IF(K18="", 0, (G18*1.1)-N18) -> 0 | P18: =P19 -> (예)2026-05-31 | Q18: =IF(OR(K18="",O18=0),"",IF(TODAY()-K18>=91,"장기미수",IF(TODAY()-K18>=31,"관리","")))
B19: =IF(H18="잔금", B18+1, B18) -> 6 | C19: =C18 -> 기술자문료_s | D19: =D18 -> (주)부영씨엔씨 | E19: =E18 -> 잠실리센츠 | G19: =F17-S19 -> 406800000 | H19: 잔금 | I19: 45992 | J19: =J18 -> 45966 | O19: =IF(K19="", 0, (G19*1.1)-N19) -> 0 | P19: (예)2026-05-31 | Q19: =IF(OR(K19="",O19=0),"",IF(TODAY()-K19>=91,"장기미수",IF(TODAY()-K19>=31,"관리","")))
B20: =IF(H19="잔금", B19+1, B19) -> 7 | C20: 기술자문료 | D20: (주)청명이앤디 | E20: 일광자이푸르지오1단지 아파트 | F20: 12000000 | H20: 선금 | I20: 46076 | J20: 46104 | O20: =IF(K20="", 0, (G20*1.1)-N20) -> 0 | P20: =P22 -> 46128 | Q20: =IF(OR(K20="",O20=0),"",IF(TODAY()-K20>=91,"장기미수",IF(TODAY()-K20>=31,"관리","")))
B21: =IF(H20="잔금", B20+1, B20) -> 7 | C21: =C20 -> 기술자문료 | D21: =D20 -> (주)청명이앤디 | E21: =E20 -> 일광자이푸르지오1단지 아파트 | H21: 중도금 | I21: =I20 -> 46076 | J21: =J20 -> 46104 | O21: =IF(K21="", 0, (G21*1.1)-N21) -> 0 | P21: =P22 -> 46128 | Q21: =IF(OR(K21="",O21=0),"",IF(TODAY()-K21>=91,"장기미수",IF(TODAY()-K21>=31,"관리","")))
B22: =IF(H21="잔금", B21+1, B21) -> 7 | C22: =C21 -> 기술자문료 | D22: =D21 -> (주)청명이앤디 | E22: =E21 -> 일광자이푸르지오1단지 아파트 | G22: =F20-S22 -> 12000000 | H22: 잔금 | I22: =I21 -> 46076 | J22: =J21 -> 46104 | K22: 46148 | L22: =IF(K22<>"", K22+30, "") -> 46178 | O22: =IF(K22="", 0, (G22*1.1)-N22) -> 13200000 | P22: 46128 | Q22: =IF(OR(K22="",O22=0),"",IF(TODAY()-K22>=91,"장기미수",IF(TODAY()-K22>=31,"관리",""))) | T22: 19800000
B23: =IF(H22="잔금", B22+1, B22) -> 8 | C23: 기술자문료 | D23: (주)청명이앤디 | E23: 일광자이푸르지오2단지아파트 | F23: 39700000 | G23: =F23*20% -> 7940000 | H23: 선금 | I23: 46076 | J23: 46073 | K23: 46125 | L23: =IF(K23<>"", K23+20, "") -> 46145 | O23: =IF(K23="", 0, (G23*1.1)-N23) -> 8734000 | P23: =P25 -> 46161 | Q23: =IF(OR(K23="",O23=0),"",IF(TODAY()-K23>=91,"장기미수",IF(TODAY()-K23>=31,"관리",""))) -> 관리
B24: =IF(H23="잔금", B23+1, B23) -> 8 | C24: =C23 -> 기술자문료 | D24: =D23 -> (주)청명이앤디 | E24: =E23 -> 일광자이푸르지오2단지아파트 | G24: =F23*40% -> 15880000 | H24: 중도금 | I24: =I23 -> 46076 | J24: =J23 -> 46073 | K24: 46148 | L24: =IF(K24<>"", K24+20, "") -> 46168 | O24: =IF(K24="", 0, (G24*1.1)-N24) -> 17468000 | P24: =P25 -> 46161 | Q24: =IF(OR(K24="",O24=0),"",IF(TODAY()-K24>=91,"장기미수",IF(TODAY()-K24>=31,"관리","")))
B25: =IF(H24="잔금", B24+1, B24) -> 8 | C25: =C24 -> 기술자문료 | D25: =D24 -> (주)청명이앤디 | E25: =E24 -> 일광자이푸르지오2단지아파트 | G25: =(F23*40%)-S25 -> 15880000 | H25: 잔금 | I25: =I24 -> 46076 | J25: =J24 -> 46073 | O25: =IF(K25="", 0, (G25*1.1)-N25) -> 0 | P25: 46161 | Q25: =IF(OR(K25="",O25=0),"",IF(TODAY()-K25>=91,"장기미수",IF(TODAY()-K25>=31,"관리",""))) | T25: 31680000
B26: =IF(H25="잔금", B25+1, B25) -> 9 | C26: 기술자문료 | D26: ㈜청람건설 | E26: 혁신도시 엘에이치5단지아파트 | F26: 18700000 | H26: 선금 | I26: 46133 | J26: 46073 | O26: =IF(K26="", 0, (G26*1.1)-N26) -> 0 | P26: =P28 -> 46161 | Q26: =IF(OR(K26="",O26=0),"",IF(TODAY()-K26>=91,"장기미수",IF(TODAY()-K26>=31,"관리","")))
B27: =IF(H26="잔금", B26+1, B26) -> 9 | C27: =C26 -> 기술자문료 | D27: =D26 -> ㈜청람건설 | E27: =E26 -> 혁신도시 엘에이치5단지아파트 | H27: 중도금 | I27: =I26 -> 46133 | J27: =J26 -> 46073 | O27: =IF(K27="", 0, (G27*1.1)-N27) -> 0 | P27: =P28 -> 46161 | Q27: =IF(OR(K27="",O27=0),"",IF(TODAY()-K27>=91,"장기미수",IF(TODAY()-K27>=31,"관리","")))
B28: =IF(H27="잔금", B27+1, B27) -> 9 | C28: =C27 -> 기술자문료 | D28: =D27 -> ㈜청람건설 | E28: =E27 -> 혁신도시 엘에이치5단지아파트 | G28: =F26-S28 -> 18700000 | H28: 잔금 | I28: =I27 -> 46133 | J28: =J27 -> 46073 | O28: =IF(K28="", 0, (G28*1.1)-N28) -> 0 | P28: 46161 | Q28: =IF(OR(K28="",O28=0),"",IF(TODAY()-K28>=91,"장기미수",IF(TODAY()-K28>=31,"관리","")))
B29: =IF(H28="잔금", B28+1, B28) -> 10 | C29: 기술자문료_s | D29: 여름건설㈜ | E29: 죽전현대홈타운아파트 | F29: 2000000 | H29: 선금 | I29: 46128 | J29: 46119 | O29: =IF(K29="", 0, (G29*1.1)-N29) -> 0 | P29: =P31 -> 46126 | Q29: =IF(OR(K29="",O29=0),"",IF(TODAY()-K29>=91,"장기미수",IF(TODAY()-K29>=31,"관리","")))
B30: =IF(H29="잔금", B29+1, B29) -> 10 | C30: =C29 -> 기술자문료_s | D30: =D29 -> 여름건설㈜ | E30: =E29 -> 죽전현대홈타운아파트 | H30: 중도금 | I30: =I29 -> 46128 | J30: =J29 -> 46119 | O30: =IF(K30="", 0, (G30*1.1)-N30) -> 0 | P30: =P31 -> 46126 | Q30: =IF(OR(K30="",O30=0),"",IF(TODAY()-K30>=91,"장기미수",IF(TODAY()-K30>=31,"관리","")))
B31: =IF(H30="잔금", B30+1, B30) -> 10 | C31: =C30 -> 기술자문료_s | D31: =D30 -> 여름건설㈜ | E31: =E30 -> 죽전현대홈타운아파트 | G31: =F29-S31 -> 2000000 | H31: 잔금 | I31: =I30 -> 46128 | J31: =J30 -> 46119 | K31: 46164 | L31: =IF(K31<>"", K31+30, "") -> 46194 | O31: =IF(K31="", 0, (G31*1.1)-N31) -> 2200000 | P31: 46126 | Q31: =IF(OR(K31="",O31=0),"",IF(TODAY()-K31>=91,"장기미수",IF(TODAY()-K31>=31,"관리","")))
B32: =IF(H31="잔금", B31+1, B31) -> 11 | C32: 기술자문료_s | D32: 코지건설㈜ | E32: 송도캐슬&해모로아파트 | F32: 40100000 | H32: 선금 | I32: 46127 | J32: 46001 | O32: =IF(K32="", 0, (G32*1.1)-N32) -> 0 | P32: =P34 -> 46112 | Q32: =IF(OR(K32="",O32=0),"",IF(TODAY()-K32>=91,"장기미수",IF(TODAY()-K32>=31,"관리","")))
B33: =IF(H32="잔금", B32+1, B32) -> 11 | C33: =C32 -> 기술자문료_s | D33: =D32 -> 코지건설㈜ | E33: =E32 -> 송도캐슬&해모로아파트 | H33: 중도금 | I33: =I32 -> 46127 | J33: =J32 -> 46001 | O33: =IF(K33="", 0, (G33*1.1)-N33) -> 0 | P33: =P34 -> 46112 | Q33: =IF(OR(K33="",O33=0),"",IF(TODAY()-K33>=91,"장기미수",IF(TODAY()-K33>=31,"관리","")))
B34: =IF(H33="잔금", B33+1, B33) -> 11 | C34: =C33 -> 기술자문료_s | D34: =D33 -> 코지건설㈜ | E34: =E33 -> 송도캐슬&해모로아파트 | G34: =F32-S34 -> 40100000 | H34: 잔금 | I34: =I33 -> 46127 | J34: =J33 -> 46001 | O34: =IF(K34="", 0, (G34*1.1)-N34) -> 0 | P34: 46112 | Q34: =IF(OR(K34="",O34=0),"",IF(TODAY()-K34>=91,"장기미수",IF(TODAY()-K34>=31,"관리","")))
B35: =IF(H34="잔금", B34+1, B34) -> 12 | C35: 기술자문료_s | D35: 코지건설㈜ | E35: 평택비전지웰푸르지오아파트 | F35: 433650000 | H35: 선금 | I35: 46139 | J35: 46097 | O35: =IF(K35="", 0, (G35*1.1)-N35) -> 0 | P35: =P37 -> (예)2026-07-15 | Q35: =IF(OR(K35="",O35=0),"",IF(TODAY()-K35>=91,"장기미수",IF(TODAY()-K35>=31,"관리","")))
B36: =IF(H35="잔금", B35+1, B35) -> 12 | C36: =C35 -> 기술자문료_s | D36: =D35 -> 코지건설㈜ | E36: =E35 -> 평택비전지웰푸르지오아파트 | H36: 중도금 | I36: =I35 -> 46139 | J36: =J35 -> 46097 | O36: =IF(K36="", 0, (G36*1.1)-N36) -> 0 | P36: =P37 -> (예)2026-07-15 | Q36: =IF(OR(K36="",O36=0),"",IF(TODAY()-K36>=91,"장기미수",IF(TODAY()-K36>=31,"관리","")))
B37: =IF(H36="잔금", B36+1, B36) -> 12 | C37: =C36 -> 기술자문료_s | D37: =D36 -> 코지건설㈜ | E37: =E36 -> 평택비전지웰푸르지오아파트 | G37: =F35-S37 -> 433650000 | H37: 잔금 | I37: =I36 -> 46139 | J37: =J36 -> 46097 | O37: =IF(K37="", 0, (G37*1.1)-N37) -> 0 | P37: (예)2026-07-15 | Q37: =IF(OR(K37="",O37=0),"",IF(TODAY()-K37>=91,"장기미수",IF(TODAY()-K37>=31,"관리","")))
B38: =IF(H37="잔금", B37+1, B37) -> 13 | C38: 기술자문료_s | D38: 코지건설㈜ | E38: 동수원월드메르디앙아파트 | F38: 5390000 | H38: 선금 | I38: 46135 | J38: 46055 | O38: =IF(K38="", 0, (G38*1.1)-N38) -> 0 | P38: =P40 -> 46112 | Q38: =IF(OR(K38="",O38=0),"",IF(TODAY()-K38>=91,"장기미수",IF(TODAY()-K38>=31,"관리","")))
B39: =IF(H38="잔금", B38+1, B38) -> 13 | C39: =C38 -> 기술자문료_s | D39: =D38 -> 코지건설㈜ | E39: =E38 -> 동수원월드메르디앙아파트 | H39: 중도금 | I39: =I38 -> 46135 | J39: =J38 -> 46055 | O39: =IF(K39="", 0, (G39*1.1)-N39) -> 0 | P39: =P40 -> 46112 | Q39: =IF(OR(K39="",O39=0),"",IF(TODAY()-K39>=91,"장기미수",IF(TODAY()-K39>=31,"관리","")))
B40: =IF(H39="잔금", B39+1, B39) -> 13 | C40: =C39 -> 기술자문료_s | D40: =D39 -> 코지건설㈜ | E40: =E39 -> 동수원월드메르디앙아파트 | G40: =F38-S40 -> 5390000 | H40: 잔금 | I40: =I39 -> 46135 | J40: =J39 -> 46055 | O40: =IF(K40="", 0, (G40*1.1)-N40) -> 0 | P40: 46112 | Q40: =IF(OR(K40="",O40=0),"",IF(TODAY()-K40>=91,"장기미수",IF(TODAY()-K40>=31,"관리","")))
...

Sheet 특허료
B1: 순번 | C1: 매출구분 | D1: 업체명 | E1: 현장명 | F1: 낙찰금액(v-) | G1: 특허료 비율 | H1: 자재판매(v-) | I1: 매출액(v-) | J1: 공문발송일 | K1: 매출일 | L1: 입금예정일 | M1: 입금일 | N1: 입금액(v+) | O1: 수금예정액(V+) | P1: 입금지연
B2: 1 | C2: 특허기술자문료 | D2: (주)효덕산업 | E2: 신정현대6차아파트 | F2: 396000000 | G2: 0.01 | H2: 315000 | I2: =(F2*G2)-(H2*50%) -> 3802500 | J2: 45999 | K2: 46027 | L2: =IF(K2<>"", K2+30, "") -> 46057 | M2: 46112 | N2: =I2*1.1 -> 4182750 | O2: =IF(K2="", 0, (I2*1.1)-N2) -> 0 | P2: =IF(OR(K2="",O2=0),"",IF(TODAY()-K2>=91,"장기미수",IF(TODAY()-K2>=31,"입금지연","")))
B3: =IF(E3="","",COUNTA($E$2:E3)) -> 2 | C3: 특허기술자문료 | D3: 석진건설(주) | E3: 포레나광교상현아파트 | F3: 809200000 | G3: 0.01 | H3: 15907900 | I3: =(F3*G3)-(H3*50%) -> 138050 | J3: 46020 | K3: 46028 | L3: =IF(K3<>"", K3+30, "") -> 46058 | M3: 46091 | N3: =I3*1.1 -> 151855 | O3: =IF(K3="", 0, (I3*1.1)-N3) -> 0 | P3: =IF(OR(K3="",O3=0),"",IF(TODAY()-K3>=91,"장기미수",IF(TODAY()-K3>=31,"입금지연","")))
B4: =IF(E4="","",COUNTA($E$2:E4)) -> 3 | C4: 특허기술자문료 | D4: 석진건설(주) | E4: 동탄역더샵센트럴시티2차아파트 | F4: 830000000 | G4: 0.01 | H4: 3249900 | I4: =(F4*G4)-(H4*50%) -> 6675050 | J4: 46020 | K4: 46028 | L4: =IF(K4<>"", K4+30, "") -> 46058 | M4: 46091 | N4: =I4*1.1 -> 7342555 | O4: =IF(K4="", 0, (I4*1.1)-N4) -> 0 | P4: =IF(OR(K4="",O4=0),"",IF(TODAY()-K4>=91,"장기미수",IF(TODAY()-K4>=31,"입금지연","")))
B5: =IF(E5="","",COUNTA($E$2:E5)) -> 4 | C5: 특허기술자문료 | D5: 한별이엔씨(주) | E5: LG원당자이아파트 | F5: 17950000 | G5: 0.01 | H5: 0 | I5: =(F5*G5)-(H5*50%) -> 179500 | J5: 46020 | K5: 46034 | L5: =IF(K5<>"", K5+30, "") -> 46064 | M5: 46037 | N5: =I5*1.1 -> 197450 | O5: =IF(K5="", 0, (I5*1.1)-N5) -> 0 | P5: =IF(OR(K5="",O5=0),"",IF(TODAY()-K5>=91,"장기미수",IF(TODAY()-K5>=31,"입금지연","")))
B6: =IF(E6="","",COUNTA($E$2:E6)) -> 5 | C6: 특허기술자문료 | D6: (주)다산종합건설 | E6: 지행역동원베네스트 | F6: 289800000 | G6: 0.01 | H6: 4840000 | I6: =(F6*G6)-(H6*50%) -> 478000 | J6: 46052 | K6: 46052 | L6: =IF(K6<>"", K6+30, "") -> 46082 | M6: 46059 | N6: =I6*1.1 -> 525800 | O6: =IF(K6="", 0, (I6*1.1)-N6) -> 0 | P6: =IF(OR(K6="",O6=0),"",IF(TODAY()-K6>=91,"장기미수",IF(TODAY()-K6>=31,"입금지연","")))
B7: =IF(E7="","",COUNTA($E$2:E7)) -> 6 | C7: 특허기술자문료 | D7: 주식회사 예은건설 | E7: 천호현대코아아파트 | G7: 0.01 | I7: -883400 | J7: 46048 | K7: 46023 | L7: =IF(K7<>"", K7+30, "") -> 46053 | M7: 46052 | N7: =I7*1.1 -> -971740 | O7: =IF(K7="", 0, (I7*1.1)-N7) -> 0 | P7: =IF(OR(K7="",O7=0),"",IF(TODAY()-K7>=91,"장기미수",IF(TODAY()-K7>=31,"입금지연","")))
B8: =IF(E8="","",COUNTA($E$2:E8)) -> 7 | C8: 특허기술자문료 | D8: 주식회사 삼흥티에스건설 | E8: 협성그린타운아파트 | F8: 245400000 | G8: 0.01 | H8: 2494600 | I8: =(F8*G8)-(H8*50%) -> 1206700 | J8: 46020 | K8: 46058 | L8: =IF(K8<>"", K8+30, "") -> 46088 | M8: 46080 | N8: =I8*1.1 -> 1327370 | O8: =IF(K8="", 0, (I8*1.1)-N8) -> 0 | P8: =IF(OR(K8="",O8=0),"",IF(TODAY()-K8>=91,"장기미수",IF(TODAY()-K8>=31,"입금지연","")))
B9: =IF(E9="","",COUNTA($E$2:E9)) -> 8 | C9: 특허기술자문료 | D9: 동일산건㈜ | E9: 백현마을8단지아파트 | F9: 469000000 | G9: 0.01 | H9: 380000 | I9: =(F9*G9)-(H9*50%) -> 4500000 | J9: 46055 | K9: 46092 | L9: =IF(K9<>"", K9+30, "") -> 46122 | M9: 46127 | N9: =I9*1.1 -> 4950000 | O9: =IF(K9="", 0, (I9*1.1)-N9) -> 0 | P9: =IF(OR(K9="",O9=0),"",IF(TODAY()-K9>=91,"장기미수",IF(TODAY()-K9>=31,"입금지연","")))
B10: =IF(E10="","",COUNTA($E$2:E10)) -> 9 | C10: 특허기술자문료 | D10: 엘케이개발㈜ | E10: 신당삼성아파트 | F10: 325000000 | G10: 0.005 | H10: 1335000 | I10: 1291250 | J10: 46093 | K10: 46094 | L10: =IF(K10<>"", K10+30, "") -> 46124 | M10: 46112 | N10: =I10*1.1 -> 1420375 | O10: =IF(K10="", 0, (I10*1.1)-N10) -> 0 | P10: =IF(OR(K10="",O10=0),"",IF(TODAY()-K10>=91,"장기미수",IF(TODAY()-K10>=31,"입금지연","")))
B11: =IF(E11="","",COUNTA($E$2:E11)) -> 10 | C11: 특허기술자문료 | D11: 코지건설㈜ | E11: 금호두산아파트 | F11: 262800000 | G11: 0.01 | H11: 413000 | I11: =(F11*G11)-(H11*50%) -> 2421500 | J11: 46122 | K11: 46122 | L11: =IF(K11<>"", K11+30, "") -> 46152 | M11: 46127 | N11: =I11*1.1 -> 2663650 | O11: =IF(K11="", 0, (I11*1.1)-N11) -> 0 | P11: =IF(OR(K11="",O11=0),"",IF(TODAY()-K11>=91,"장기미수",IF(TODAY()-K11>=31,"입금지연","")))
B12: =IF(E12="","",COUNTA($E$2:E12)) -> 11 | C12: 특허기술자문료 | D12: (주)지건씨앤씨 | E12: 면목풍림아파트 | F12: 39500000 | G12: 0.01 | H12: 190800 | I12: =(F12*G12)-(H12*50%) -> 299600 | J12: 46020 | K12: 46126 | L12: =IF(K12<>"", K12+30, "") -> 46156 | M12: 46142 | N12: =I12*1.1 -> 329560 | O12: =IF(K12="", 0, (I12*1.1)-N12) -> 0 | P12: =IF(OR(K12="",O12=0),"",IF(TODAY()-K12>=91,"장기미수",IF(TODAY()-K12>=31,"입금지연","")))
B13: =IF(E13="","",COUNTA($E$2:E13)) -> 12 | C13: 특허기술자문료 | D13: (주)무한하우징 | E13: 대림3동현대아파트 | F13: 142000000 | G13: 0.01 | H13: 896000 | I13: =(F13*G13)-(H13*50%) -> 972000 | J13: 46134 | K13: 46134 | L13: =IF(K13<>"", K13+30, "") -> 46164 | M13: 46141 | N13: =I13*1.1 -> 1069200 | O13: =IF(K13="", 0, (I13*1.1)-N13) -> 0 | P13: =IF(OR(K13="",O13=0),"",IF(TODAY()-K13>=91,"장기미수",IF(TODAY()-K13>=31,"입금지연","")))
B14: =IF(E14="","",COUNTA($E$2:E14)) -> 13 | C14: 특허기술자문료 | D14: 천강건설㈜ | E14: 학마을서원아파트 | F14: 46700000 | G14: 0.01 | H14: 0 | I14: =(F14*G14)-(H14*50%) -> 467000 | J14: 46140 | K14: 46141 | L14: =IF(K14<>"", K14+30, "") -> 46171 | M14: 46142 | N14: =I14*1.1 -> 513700 | O14: =IF(K14="", 0, (I14*1.1)-N14) -> 0 | P14: =IF(OR(K14="",O14=0),"",IF(TODAY()-K14>=91,"장기미수",IF(TODAY()-K14>=31,"입금지연","")))
B15: =IF(E15="","",COUNTA($E$2:E15)) -> 14 | C15: 특허기술자문료 | D15: (주)경하이앤씨 | E15: 이천롯데캐슬골드스카이아파트 | F15: 35000000 | G15: 0.01 | H15: 0 | I15: =(F15*G15)-(H15*50%) -> 350000 | J15: 46153 | K15: 46154 | L15: =IF(K15<>"", K15+30, "") -> 46184 | M15: 46154 | N15: =I15*1.1 -> 385000 | O15: =IF(K15="", 0, (I15*1.1)-N15) -> 0 | P15: =IF(OR(K15="",O15=0),"",IF(TODAY()-K15>=91,"장기미수",IF(TODAY()-K15>=31,"입금지연","")))
B16: =IF(E16="","",COUNTA($E$2:E16)) -> 15 | C16: 특허기술자문료 | D16: (주)도원씨엔씨 | E16: 은행마을녹원아파트 | F16: 138000000 | G16: 0.01 | H16: 0 | I16: =(F16*G16)-(H16*50%) -> 1380000 | J16: 46153 | K16: 46154 | L16: =IF(K16<>"", K16+30, "") -> 46184 | O16: =IF(K16="", 0, (I16*1.1)-N16) -> 1518000 | P16: =IF(OR(K16="",O16=0),"",IF(TODAY()-K16>=91,"장기미수",IF(TODAY()-K16>=31,"입금지연","")))
B17: =IF(E17="","",COUNTA($E$2:E17)) -> 16 | C17: 특허기술자문료 | D17: 천강건설㈜ | E17: 미사강변센텀팰리스아파트 | F17: 1024669774 | G17: 0.01 | H17: 4628000 | I17: =(F17*G17)-(H17*50%) -> 7932697.7 | J17: 46155 | K17: 46155 | L17: =IF(K17<>"", K17+30, "") -> 46185 | M17: 46156 | N17: =I17*1.1 -> 8725967.5 | O17: =IF(K17="", 0, (I17*1.1)-N17) -> 0 | P17: =IF(OR(K17="",O17=0),"",IF(TODAY()-K17>=91,"장기미수",IF(TODAY()-K17>=31,"입금지연","")))
B18: =IF(E18="","",COUNTA($E$2:E18)) -> 17 | C18: 특허기술자문료 | D18: 천강건설㈜ | E18: 녹번역센트레빌아파트 | F18: 155000000 | G18: 0.01 | H18: 0 | I18: =(F18*G18)-(H18*50%) -> 1550000 | J18: 46155 | K18: 46157 | L18: =IF(K18<>"", K18+30, "") -> 46187 | M18: 46157 | N18: =I18*1.1 -> 1705000 | O18: =IF(K18="", 0, (I18*1.1)-N18) -> 0 | P18: =IF(OR(K18="",O18=0),"",IF(TODAY()-K18>=91,"장기미수",IF(TODAY()-K18>=31,"입금지연","")))
B19: =IF(E19="","",COUNTA($E$2:E19)) -> 18 | C19: 특허기술자문료 | D19: 삼정아이엔지건설㈜ | E19: 동백역벽산블루밍아파트 | F19: 333400000 | G19: 0.01 | H19: 889500 | I19: =(F19*G19)-(H19*50%) -> 2889250 | J19: 46161 | K19: 46161 | L19: =IF(K19<>"", K19+30, "") -> 46191 | O19: =IF(K19="", 0, (I19*1.1)-N19) -> 3178175 | P19: =IF(OR(K19="",O19=0),"",IF(TODAY()-K19>=91,"장기미수",IF(TODAY()-K19>=31,"입금지연","")))
B20: =IF(E20="","",COUNTA($E$2:E20)) -> 19 | C20: 특허기술자문료 | D20: ㈜효덕산업 | E20: 송도베르디움더퍼스트아파트 | F20: 1102000000 | G20: 0.01 | H20: 2133800 | I20: =(F20*G20)-(H20*50%) -> 9953100 | J20: 46155 | K20: 46169 | L20: =IF(K20<>"", K20+30, "") -> 46199 | O20: =IF(K20="", 0, (I20*1.1)-N20) -> 10948410 | P20: =IF(OR(K20="",O20=0),"",IF(TODAY()-K20>=91,"장기미수",IF(TODAY()-K20>=31,"입금지연","")))
B21: =IF(E21="","",COUNTA($E$2:E21)) -> 20 | C21: 특허기술자문료 | D21: ㈜더원산업개발 | E21: 진달래마을신동아아파트 | I21: =10000000/1.1 -> 9090909.1 | J21: 46170 | K21: 46170 | L21: =IF(K21<>"", K21+30, "") -> 46200 | M21: 46171 | N21: =I21*1.1 -> 10000000 | O21: =IF(K21="", 0, (I21*1.1)-N21) -> 0 | P21: =IF(OR(K21="",O21=0),"",IF(TODAY()-K21>=91,"장기미수",IF(TODAY()-K21>=31,"입금지연","")))
B22: =IF(E22="","",COUNTA($E$2:E22)) -> 21 | C22: 특허기술자문료 | D22: 와이티파트너스㈜ | E22: 하남성원상떼빌아파트 | F22: 135930000 | G22: 0.01 | H22: 2000200 | I22: =(F22*G22)-(H22*50%) -> 359200 | J22: 46168 | K22: 46174 | L22: =IF(K22<>"", K22+30, "") -> 46204 | O22: =IF(K22="", 0, (I22*1.1)-N22) -> 395120 | P22: =IF(OR(K22="",O22=0),"",IF(TODAY()-K22>=91,"장기미수",IF(TODAY()-K22>=31,"입금지연","")))
B23: =IF(E23="","",COUNTA($E$2:E23)) | O23: =IF(K23="", 0, (I23*1.1)-N23) -> 0 | P23: =IF(OR(K23="",O23=0),"",IF(TODAY()-K23>=91,"장기미수",IF(TODAY()-K23>=31,"입금지연","")))
B24: =IF(E24="","",COUNTA($E$2:E24)) | O24: =IF(K24="", 0, (I24*1.1)-N24) -> 0 | P24: =IF(OR(K24="",O24=0),"",IF(TODAY()-K24>=91,"장기미수",IF(TODAY()-K24>=31,"입금지연","")))
B25: =IF(E25="","",COUNTA($E$2:E25)) | O25: =IF(K25="", 0, (I25*1.1)-N25) -> 0 | P25: =IF(OR(K25="",O25=0),"",IF(TODAY()-K25>=91,"장기미수",IF(TODAY()-K25>=31,"입금지연","")))

Sheet 자재판매
